/Users/daniel/BA_SketchFix_Evaluation/Evaluation/venv/bin/python /Users/daniel/BA_SketchFix_Evaluation/Evaluation/SetupBug/replace_bug.py



#######################################################################################################
                             PROJECT: fastapi
#######################################################################################################
CLONING PROJECT:
✓ SUCCESSFUL! This project is already cloned: https://github.com/tiangolo/fastapi
.......................................................................................................
BUGGY LINES:
37,71,90,97,105
501
63,64,65,66,67
183
100
632,633,634
22
352
577

134,139
115,116,117,118
290,293,294,302
102,123,223

18,19,20,21,22
.......................................................................................................

+*+*+*+*+*+*+*+*+*+*+*+*+*+*+*+*+*+*+*+*+*+*+*+*+*+*+*+*+*+*+*+*+*+*+*+*+*+*+*+*+*+*+*+*+*+*+*+*+*+*+*+

                                          BUG: 1

+*+*+*+*+*+*+*+*+*+*+*+*+*+*+*+*+*+*+*+*+*+*+*+*+*+*+*+*+*+*+*+*+*+*+*+*+*+*+*+*+*+*+*+*+*+*+*+*+*+*+*+
bug_file = /Users/daniel/BA_SketchFix_Evaluation/Evaluation/Projects/fastapi/fastapi/applications.py
bug_test_file = /Users/daniel/BA_SketchFix_Evaluation/Evaluation/Projects/fastapi/tests/test_jsonable_encoder.py
GIT RESET TO: 766157bfb4e7dfccba09ab398e8ec444d14e947c
HEAD is now at 766157b :memo: Update release notes
TEST EXECUTION:
...........................
x TEST FAILS
✓ PyFix is started...

~~~~~~~~~~~~~~~~~~~~~~~~~~~~~~~~~~~~~~~~~~~~~~~~~~~~~~~~~~~~~~~~~~~~~~~~~~~~~~~~~~~~~~~~~~~~~~~~~~~~~~~

	                              PySketchFix®: Sketches are created.

~~~~~~~~~~~~~~~~~~~~~~~~~~~~~~~~~~~~~~~~~~~~~~~~~~~~~~~~~~~~~~~~~~~~~~~~~~~~~~~~~~~~~~~~~~~~~~~~~~~~~~~
PySketchFix will run with:
bug file: /Users/daniel/BA_SketchFix_Evaluation/Evaluation/Projects/fastapi/fastapi/applications.py
~~~~~~~~~~~~~~~~~~~~~~~~~~~~~~~~~~~~~~~~~~~~~~~~~~~~~~~~~~~~~~~~~~~~~~~~~~~~~~~~~~~~~~~~~~~~~~~~~~~~~~~
test_jsonable_encoder (unittest.loader._FailedTest) ... ERROR

======================================================================
ERROR: test_jsonable_encoder (unittest.loader._FailedTest)
----------------------------------------------------------------------
ImportError: Failed to import test module: test_jsonable_encoder
Traceback (most recent call last):
  File "/usr/local/Cellar/python/3.7.7/Frameworks/Python.framework/Versions/3.7/lib/python3.7/unittest/loader.py", line 436, in _find_test_path
    module = self._get_module_from_name(name)
  File "/usr/local/Cellar/python/3.7.7/Frameworks/Python.framework/Versions/3.7/lib/python3.7/unittest/loader.py", line 377, in _get_module_from_name
    __import__(name)
  File "/Users/daniel/BA_SketchFix_Evaluation/Evaluation/Projects/fastapi/tests/test_jsonable_encoder.py", line 5, in <module>
    import pytest
ModuleNotFoundError: No module named 'pytest'


----------------------------------------------------------------------
Ran 1 test in 0.001s

FAILED (errors=1)
The suspicious lines which are taken are: [37, 71, 90, 97, 105]
~~~~~~~~~~~~~~~~~~~~~~~~~~~~~~~~~~~~~~~~~~~~~~~~~~~~~~~~~~~~~~~~~~~~~~~~~~~~~~~~~~~~~~~~~~~~~~~~~~~~~~~
Start transforming line: 37
x Fail! Line: 37 could not be transformed: 'version str = "0.1.0",'
Start transforming line: 71
x Fail! Line: 71 could not be transformed: 'self.openapi_prefix = openapi_prefix.rstrip("/")'
Start transforming line: 90
x Fail! Line: 90 could not be transformed: 'openapi(self) -> Dict'
Start transforming line: 97
✓
Start transforming line: 105
x Fail! Line: 105 could not be transformed: 'async openapi(req Request) -> JSONResponse'
~~~~~~~~~~~~~~~~~~~~~~~~~~~~~~~~~~~~~~~~~~~~~~~~~~~~~~~~~~~~~~~~~~~~~~~~~~~~~~~~~~~~~~~~~~~~~~~~~~~~~~~
Start creating 1 sketches.
✓
~~~~~~~~~~~~~~~~~~~~~~~~~~~~~~~~~~~~~~~~~~~~~~~~~~~~~~~~~~~~~~~~~~~~~~~~~~~~~~~~~~~~~~~~~~~~~~~~~~~~~~~
x Lines where no transformation is found:[37, 71, 90, 105]
✓ Number of created sketches:1
Time needed: 0.03 minutes.

+*+*+*+*+*+*+*+*+*+*+*+*+*+*+*+*+*+*+*+*+*+*+*+*+*+*+*+*+*+*+*+*+*+*+*+*+*+*+*+*+*+*+*+*+*+*+*+*+*+*+*+

                                          BUG: 2

+*+*+*+*+*+*+*+*+*+*+*+*+*+*+*+*+*+*+*+*+*+*+*+*+*+*+*+*+*+*+*+*+*+*+*+*+*+*+*+*+*+*+*+*+*+*+*+*+*+*+*+
bug_file = /Users/daniel/BA_SketchFix_Evaluation/Evaluation/Projects/fastapi/fastapi/routing.py
bug_test_file = /Users/daniel/BA_SketchFix_Evaluation/Evaluation/Projects/fastapi/tests/test_ws_router.py
GIT RESET TO: 210af1fd3dc0f612a08fa02a0cb3f5adb81e5bfb
HEAD is now at 210af1f :memo: Update release notes
TEST EXECUTION:
test_ws_router (unittest.loader._FailedTest) ... ERROR

======================================================================
ERROR: test_ws_router (unittest.loader._FailedTest)
----------------------------------------------------------------------
ImportError: Failed to import test module: test_ws_router
Traceback (most recent call last):
  File "/usr/local/Cellar/python/3.7.7/Frameworks/Python.framework/Versions/3.7/lib/python3.7/unittest/loader.py", line 436, in _find_test_path
    module = self._get_module_from_name(name)
  File "/usr/local/Cellar/python/3.7.7/Frameworks/Python.framework/Versions/3.7/lib/python3.7/unittest/loader.py", line 377, in _get_module_from_name
    __import__(name)
  File "/Users/daniel/BA_SketchFix_Evaluation/Evaluation/Projects/fastapi/tests/test_ws_router.py", line 1, in <module>
    from fastapi import APIRouter, FastAPI, WebSocket
ModuleNotFoundError: No module named 'fastapi'


----------------------------------------------------------------------
Ran 1 test in 0.001s

FAILED (errors=1)
...........................
x TEST FAILS
✓ PyFix is started...

~~~~~~~~~~~~~~~~~~~~~~~~~~~~~~~~~~~~~~~~~~~~~~~~~~~~~~~~~~~~~~~~~~~~~~~~~~~~~~~~~~~~~~~~~~~~~~~~~~~~~~~

	                              PySketchFix®: Sketches are created.

~~~~~~~~~~~~~~~~~~~~~~~~~~~~~~~~~~~~~~~~~~~~~~~~~~~~~~~~~~~~~~~~~~~~~~~~~~~~~~~~~~~~~~~~~~~~~~~~~~~~~~~
PySketchFix will run with:
bug file: /Users/daniel/BA_SketchFix_Evaluation/Evaluation/Projects/fastapi/fastapi/routing.py
~~~~~~~~~~~~~~~~~~~~~~~~~~~~~~~~~~~~~~~~~~~~~~~~~~~~~~~~~~~~~~~~~~~~~~~~~~~~~~~~~~~~~~~~~~~~~~~~~~~~~~~
The suspicious lines which are taken are: [501]
~~~~~~~~~~~~~~~~~~~~~~~~~~~~~~~~~~~~~~~~~~~~~~~~~~~~~~~~~~~~~~~~~~~~~~~~~~~~~~~~~~~~~~~~~~~~~~~~~~~~~~~
Start transforming line: 501
✓
~~~~~~~~~~~~~~~~~~~~~~~~~~~~~~~~~~~~~~~~~~~~~~~~~~~~~~~~~~~~~~~~~~~~~~~~~~~~~~~~~~~~~~~~~~~~~~~~~~~~~~~
Start creating 2 sketches.
✓
~~~~~~~~~~~~~~~~~~~~~~~~~~~~~~~~~~~~~~~~~~~~~~~~~~~~~~~~~~~~~~~~~~~~~~~~~~~~~~~~~~~~~~~~~~~~~~~~~~~~~~~
x Lines where no transformation is found:[]
✓ Number of created sketches:2
Time needed: 0.02 minutes.

+*+*+*+*+*+*+*+*+*+*+*+*+*+*+*+*+*+*+*+*+*+*+*+*+*+*+*+*+*+*+*+*+*+*+*+*+*+*+*+*+*+*+*+*+*+*+*+*+*+*+*+

                                          BUG: 3

+*+*+*+*+*+*+*+*+*+*+*+*+*+*+*+*+*+*+*+*+*+*+*+*+*+*+*+*+*+*+*+*+*+*+*+*+*+*+*+*+*+*+*+*+*+*+*+*+*+*+*+
bug_file = /Users/daniel/BA_SketchFix_Evaluation/Evaluation/Projects/fastapi/fastapi/routing.py
bug_test_file = /Users/daniel/BA_SketchFix_Evaluation/Evaluation/Projects/fastapi/tests/test_serialize_response_model.py
GIT RESET TO: 869c7389e22dc9ad659940fa271da76c4f3ba3b1
HEAD is now at 869c738 :memo: Update release notes
TEST EXECUTION:

----------------------------------------------------------------------
Ran 0 tests in 0.000s

OK
...........................
✓ SUCCESSFUL! TEST PASSES
✓ PyFix is started...

~~~~~~~~~~~~~~~~~~~~~~~~~~~~~~~~~~~~~~~~~~~~~~~~~~~~~~~~~~~~~~~~~~~~~~~~~~~~~~~~~~~~~~~~~~~~~~~~~~~~~~~

	                              PySketchFix®: Sketches are created.

~~~~~~~~~~~~~~~~~~~~~~~~~~~~~~~~~~~~~~~~~~~~~~~~~~~~~~~~~~~~~~~~~~~~~~~~~~~~~~~~~~~~~~~~~~~~~~~~~~~~~~~
PySketchFix will run with:
bug file: /Users/daniel/BA_SketchFix_Evaluation/Evaluation/Projects/fastapi/fastapi/routing.py
~~~~~~~~~~~~~~~~~~~~~~~~~~~~~~~~~~~~~~~~~~~~~~~~~~~~~~~~~~~~~~~~~~~~~~~~~~~~~~~~~~~~~~~~~~~~~~~~~~~~~~~
The suspicious lines which are taken are: [63, 64, 65, 66, 67]
~~~~~~~~~~~~~~~~~~~~~~~~~~~~~~~~~~~~~~~~~~~~~~~~~~~~~~~~~~~~~~~~~~~~~~~~~~~~~~~~~~~~~~~~~~~~~~~~~~~~~~~
Start transforming line: 63
✓
Start transforming line: 64
✓
Start transforming line: 65
x Fail! Line: 65 could not be transformed: 'response_content = response_content.dict(exclude_unset=exclude_unset)'
Start transforming line: 66
x Fail! Line: 66 could not be transformed: ''
Start transforming line: 67
x Fail! Line: 67 could not be transformed: 'response_content = response_content.dict('
~~~~~~~~~~~~~~~~~~~~~~~~~~~~~~~~~~~~~~~~~~~~~~~~~~~~~~~~~~~~~~~~~~~~~~~~~~~~~~~~~~~~~~~~~~~~~~~~~~~~~~~
Start creating 107 sketches.
✓
~~~~~~~~~~~~~~~~~~~~~~~~~~~~~~~~~~~~~~~~~~~~~~~~~~~~~~~~~~~~~~~~~~~~~~~~~~~~~~~~~~~~~~~~~~~~~~~~~~~~~~~
x Lines where no transformation is found:[65, 66, 67]
✓ Number of created sketches:107
Time needed: 0.06 minutes.

+*+*+*+*+*+*+*+*+*+*+*+*+*+*+*+*+*+*+*+*+*+*+*+*+*+*+*+*+*+*+*+*+*+*+*+*+*+*+*+*+*+*+*+*+*+*+*+*+*+*+*+

                                          BUG: 4

+*+*+*+*+*+*+*+*+*+*+*+*+*+*+*+*+*+*+*+*+*+*+*+*+*+*+*+*+*+*+*+*+*+*+*+*+*+*+*+*+*+*+*+*+*+*+*+*+*+*+*+
bug_file = /Users/daniel/BA_SketchFix_Evaluation/Evaluation/Projects/fastapi/fastapi/openapi/utils.py
bug_test_file = /Users/daniel/BA_SketchFix_Evaluation/Evaluation/Projects/fastapi/tests/test_param_in_path_and_dependency.py
GIT RESET TO: 7ccd81f70653857bd8f3a15ee946aa3fb0edc2cb
HEAD is now at 7ccd81f :rocket: Update Netlify deploy action (#1047)
TEST EXECUTION:

----------------------------------------------------------------------
Ran 0 tests in 0.000s

OK
...........................
✓ SUCCESSFUL! TEST PASSES
✓ PyFix is started...

~~~~~~~~~~~~~~~~~~~~~~~~~~~~~~~~~~~~~~~~~~~~~~~~~~~~~~~~~~~~~~~~~~~~~~~~~~~~~~~~~~~~~~~~~~~~~~~~~~~~~~~

	                              PySketchFix®: Sketches are created.

~~~~~~~~~~~~~~~~~~~~~~~~~~~~~~~~~~~~~~~~~~~~~~~~~~~~~~~~~~~~~~~~~~~~~~~~~~~~~~~~~~~~~~~~~~~~~~~~~~~~~~~
PySketchFix will run with:
bug file: /Users/daniel/BA_SketchFix_Evaluation/Evaluation/Projects/fastapi/fastapi/openapi/utils.py
~~~~~~~~~~~~~~~~~~~~~~~~~~~~~~~~~~~~~~~~~~~~~~~~~~~~~~~~~~~~~~~~~~~~~~~~~~~~~~~~~~~~~~~~~~~~~~~~~~~~~~~
The suspicious lines which are taken are: [183]
~~~~~~~~~~~~~~~~~~~~~~~~~~~~~~~~~~~~~~~~~~~~~~~~~~~~~~~~~~~~~~~~~~~~~~~~~~~~~~~~~~~~~~~~~~~~~~~~~~~~~~~
Start transforming line: 183
✓
~~~~~~~~~~~~~~~~~~~~~~~~~~~~~~~~~~~~~~~~~~~~~~~~~~~~~~~~~~~~~~~~~~~~~~~~~~~~~~~~~~~~~~~~~~~~~~~~~~~~~~~
Start creating 4 sketches.
✓
~~~~~~~~~~~~~~~~~~~~~~~~~~~~~~~~~~~~~~~~~~~~~~~~~~~~~~~~~~~~~~~~~~~~~~~~~~~~~~~~~~~~~~~~~~~~~~~~~~~~~~~
x Lines where no transformation is found:[]
✓ Number of created sketches:4
Time needed: 0.02 minutes.

+*+*+*+*+*+*+*+*+*+*+*+*+*+*+*+*+*+*+*+*+*+*+*+*+*+*+*+*+*+*+*+*+*+*+*+*+*+*+*+*+*+*+*+*+*+*+*+*+*+*+*+

                                          BUG: 5

+*+*+*+*+*+*+*+*+*+*+*+*+*+*+*+*+*+*+*+*+*+*+*+*+*+*+*+*+*+*+*+*+*+*+*+*+*+*+*+*+*+*+*+*+*+*+*+*+*+*+*+
bug_file = /Users/daniel/BA_SketchFix_Evaluation/Evaluation/Projects/fastapi/fastapi/utils.py
bug_test_file = /Users/daniel/BA_SketchFix_Evaluation/Evaluation/Projects/fastapi/tests/test_filter_pydantic_sub_model.py
GIT RESET TO: 7cea84b74ca3106a7f861b774e9d215e5228728f
HEAD is now at 7cea84b :bug: Fix FastAPI serialization of Pydantic ORM mode blocking the event loop (#888)
TEST EXECUTION:
...........................
✓ SUCCESSFUL! TEST PASSES
✓ PyFix is started...

~~~~~~~~~~~~~~~~~~~~~~~~~~~~~~~~~~~~~~~~~~~~~~~~~~~~~~~~~~~~~~~~~~~~~~~~~~~~~~~~~~~~~~~~~~~~~~~~~~~~~~~

	                              PySketchFix®: Sketches are created.

~~~~~~~~~~~~~~~~~~~~~~~~~~~~~~~~~~~~~~~~~~~~~~~~~~~~~~~~~~~~~~~~~~~~~~~~~~~~~~~~~~~~~~~~~~~~~~~~~~~~~~~
PySketchFix will run with:
bug file: /Users/daniel/BA_SketchFix_Evaluation/Evaluation/Projects/fastapi/fastapi/utils.py
~~~~~~~~~~~~~~~~~~~~~~~~~~~~~~~~~~~~~~~~~~~~~~~~~~~~~~~~~~~~~~~~~~~~~~~~~~~~~~~~~~~~~~~~~~~~~~~~~~~~~~~
The suspicious lines which are taken are: [100]
~~~~~~~~~~~~~~~~~~~~~~~~~~~~~~~~~~~~~~~~~~~~~~~~~~~~~~~~~~~~~~~~~~~~~~~~~~~~~~~~~~~~~~~~~~~~~~~~~~~~~~~
Start transforming line: 100

----------------------------------------------------------------------
Ran 0 tests in 0.000s

OK
✓
~~~~~~~~~~~~~~~~~~~~~~~~~~~~~~~~~~~~~~~~~~~~~~~~~~~~~~~~~~~~~~~~~~~~~~~~~~~~~~~~~~~~~~~~~~~~~~~~~~~~~~~
Start creating 10 sketches.
✓
~~~~~~~~~~~~~~~~~~~~~~~~~~~~~~~~~~~~~~~~~~~~~~~~~~~~~~~~~~~~~~~~~~~~~~~~~~~~~~~~~~~~~~~~~~~~~~~~~~~~~~~
x Lines where no transformation is found:[]
✓ Number of created sketches:10
Time needed: 0.01 minutes.

+*+*+*+*+*+*+*+*+*+*+*+*+*+*+*+*+*+*+*+*+*+*+*+*+*+*+*+*+*+*+*+*+*+*+*+*+*+*+*+*+*+*+*+*+*+*+*+*+*+*+*+

                                          BUG: 6

+*+*+*+*+*+*+*+*+*+*+*+*+*+*+*+*+*+*+*+*+*+*+*+*+*+*+*+*+*+*+*+*+*+*+*+*+*+*+*+*+*+*+*+*+*+*+*+*+*+*+*+
bug_file = /Users/daniel/BA_SketchFix_Evaluation/Evaluation/Projects/fastapi/fastapi/dependencies/utils.py
bug_test_file = /Users/daniel/BA_SketchFix_Evaluation/Evaluation/Projects/fastapi/tests/test_forms_from_non_typing_sequences.py
GIT RESET TO: 5db99a27cf640864b4793807811848698c5ff4a2
HEAD is now at 5db99a2 :sparkles: add body to RequestValidationError for easier debugging (#853)
TEST EXECUTION:
...........................
✓ SUCCESSFUL! TEST PASSES
✓ PyFix is started...

~~~~~~~~~~~~~~~~~~~~~~~~~~~~~~~~~~~~~~~~~~~~~~~~~~~~~~~~~~~~~~~~~~~~~~~~~~~~~~~~~~~~~~~~~~~~~~~~~~~~~~~

	                              PySketchFix®: Sketches are created.

~~~~~~~~~~~~~~~~~~~~~~~~~~~~~~~~~~~~~~~~~~~~~~~~~~~~~~~~~~~~~~~~~~~~~~~~~~~~~~~~~~~~~~~~~~~~~~~~~~~~~~~
PySketchFix will run with:
bug file: /Users/daniel/BA_SketchFix_Evaluation/Evaluation/Projects/fastapi/fastapi/dependencies/utils.py
~~~~~~~~~~~~~~~~~~~~~~~~~~~~~~~~~~~~~~~~~~~~~~~~~~~~~~~~~~~~~~~~~~~~~~~~~~~~~~~~~~~~~~~~~~~~~~~~~~~~~~~
The suspicious lines which are taken are: [632, 633, 634]
~~~~~~~~~~~~~~~~~~~~~~~~~~~~~~~~~~~~~~~~~~~~~~~~~~~~~~~~~~~~~~~~~~~~~~~~~~~~~~~~~~~~~~~~~~~~~~~~~~~~~~~
Start transforming line: 632

----------------------------------------------------------------------
Ran 0 tests in 0.000s

OK
x Fail! Line: 632 could not be transformed: 'field.shape in sequence_shapes and isinstance('
Start transforming line: 633
✓
Start transforming line: 634
x Fail! Line: 634 could not be transformed: ')'
~~~~~~~~~~~~~~~~~~~~~~~~~~~~~~~~~~~~~~~~~~~~~~~~~~~~~~~~~~~~~~~~~~~~~~~~~~~~~~~~~~~~~~~~~~~~~~~~~~~~~~~
Start creating 3 sketches.
✓
~~~~~~~~~~~~~~~~~~~~~~~~~~~~~~~~~~~~~~~~~~~~~~~~~~~~~~~~~~~~~~~~~~~~~~~~~~~~~~~~~~~~~~~~~~~~~~~~~~~~~~~
x Lines where no transformation is found:[632, 634]
✓ Number of created sketches:3
Time needed: 0.03 minutes.

+*+*+*+*+*+*+*+*+*+*+*+*+*+*+*+*+*+*+*+*+*+*+*+*+*+*+*+*+*+*+*+*+*+*+*+*+*+*+*+*+*+*+*+*+*+*+*+*+*+*+*+

                                          BUG: 7

+*+*+*+*+*+*+*+*+*+*+*+*+*+*+*+*+*+*+*+*+*+*+*+*+*+*+*+*+*+*+*+*+*+*+*+*+*+*+*+*+*+*+*+*+*+*+*+*+*+*+*+
bug_file = /Users/daniel/BA_SketchFix_Evaluation/Evaluation/Projects/fastapi/fastapi/exception_handlers.py
bug_test_file = /Users/daniel/BA_SketchFix_Evaluation/Evaluation/Projects/fastapi/tests/test_multi_body_errors.py
GIT RESET TO: cc4c13e4ae3f65fc76c23962b316df4a60e0c7e0
HEAD is now at cc4c13e :bookmark: Release 0.44.0, with support for Pydantic v1 and above! :tada:
TEST EXECUTION:
test_multi_body_errors (unittest.loader._FailedTest) ... ERROR

======================================================================
ERROR: test_multi_body_errors (unittest.loader._FailedTest)
----------------------------------------------------------------------
ImportError: Failed to import test module: test_multi_body_errors
Traceback (most recent call last):
  File "/usr/local/Cellar/python/3.7.7/Frameworks/Python.framework/Versions/3.7/lib/python3.7/unittest/loader.py", line 436, in _find_test_path
    module = self._get_module_from_name(name)
  File "/usr/local/Cellar/python/3.7.7/Frameworks/Python.framework/Versions/3.7/lib/python3.7/unittest/loader.py", line 377, in _get_module_from_name
    __import__(name)
  File "/Users/daniel/BA_SketchFix_Evaluation/Evaluation/Projects/fastapi/tests/test_multi_body_errors.py", line 3, in <module>
    from fastapi import FastAPI
ModuleNotFoundError: No module named 'fastapi'


----------------------------------------------------------------------
Ran 1 test in 0.001s

FAILED (errors=1)
...........................
x TEST FAILS
✓ PyFix is started...

~~~~~~~~~~~~~~~~~~~~~~~~~~~~~~~~~~~~~~~~~~~~~~~~~~~~~~~~~~~~~~~~~~~~~~~~~~~~~~~~~~~~~~~~~~~~~~~~~~~~~~~

	                              PySketchFix®: Sketches are created.

~~~~~~~~~~~~~~~~~~~~~~~~~~~~~~~~~~~~~~~~~~~~~~~~~~~~~~~~~~~~~~~~~~~~~~~~~~~~~~~~~~~~~~~~~~~~~~~~~~~~~~~
PySketchFix will run with:
bug file: /Users/daniel/BA_SketchFix_Evaluation/Evaluation/Projects/fastapi/fastapi/exception_handlers.py
~~~~~~~~~~~~~~~~~~~~~~~~~~~~~~~~~~~~~~~~~~~~~~~~~~~~~~~~~~~~~~~~~~~~~~~~~~~~~~~~~~~~~~~~~~~~~~~~~~~~~~~
The suspicious lines which are taken are: [22]
~~~~~~~~~~~~~~~~~~~~~~~~~~~~~~~~~~~~~~~~~~~~~~~~~~~~~~~~~~~~~~~~~~~~~~~~~~~~~~~~~~~~~~~~~~~~~~~~~~~~~~~
Start transforming line: 22
x Fail! Line: 22 could not be transformed: 'status_code=HTTP_422_UNPROCESSABLE_ENTITY, content={"detail" exc.errors()}'
~~~~~~~~~~~~~~~~~~~~~~~~~~~~~~~~~~~~~~~~~~~~~~~~~~~~~~~~~~~~~~~~~~~~~~~~~~~~~~~~~~~~~~~~~~~~~~~~~~~~~~~
Start creating 0 sketches.
✓
~~~~~~~~~~~~~~~~~~~~~~~~~~~~~~~~~~~~~~~~~~~~~~~~~~~~~~~~~~~~~~~~~~~~~~~~~~~~~~~~~~~~~~~~~~~~~~~~~~~~~~~
x Lines where no transformation is found:[22]
✓ Number of created sketches:0
Time needed: 0.02 minutes.

+*+*+*+*+*+*+*+*+*+*+*+*+*+*+*+*+*+*+*+*+*+*+*+*+*+*+*+*+*+*+*+*+*+*+*+*+*+*+*+*+*+*+*+*+*+*+*+*+*+*+*+

                                          BUG: 8

+*+*+*+*+*+*+*+*+*+*+*+*+*+*+*+*+*+*+*+*+*+*+*+*+*+*+*+*+*+*+*+*+*+*+*+*+*+*+*+*+*+*+*+*+*+*+*+*+*+*+*+
bug_file = /Users/daniel/BA_SketchFix_Evaluation/Evaluation/Projects/fastapi/fastapi/routing.py
bug_test_file = /Users/daniel/BA_SketchFix_Evaluation/Evaluation/Projects/fastapi/tests/test_custom_route_class.py
GIT RESET TO: fdb6d43e103bcf7a7325d796e37c9435c9460e4c
HEAD is now at fdb6d43 :bookmark: Release 0.40.0
TEST EXECUTION:

----------------------------------------------------------------------
Ran 0 tests in 0.000s

OK
...........................
✓ SUCCESSFUL! TEST PASSES
✓ PyFix is started...

~~~~~~~~~~~~~~~~~~~~~~~~~~~~~~~~~~~~~~~~~~~~~~~~~~~~~~~~~~~~~~~~~~~~~~~~~~~~~~~~~~~~~~~~~~~~~~~~~~~~~~~

	                              PySketchFix®: Sketches are created.

~~~~~~~~~~~~~~~~~~~~~~~~~~~~~~~~~~~~~~~~~~~~~~~~~~~~~~~~~~~~~~~~~~~~~~~~~~~~~~~~~~~~~~~~~~~~~~~~~~~~~~~
PySketchFix will run with:
bug file: /Users/daniel/BA_SketchFix_Evaluation/Evaluation/Projects/fastapi/fastapi/routing.py
~~~~~~~~~~~~~~~~~~~~~~~~~~~~~~~~~~~~~~~~~~~~~~~~~~~~~~~~~~~~~~~~~~~~~~~~~~~~~~~~~~~~~~~~~~~~~~~~~~~~~~~
The suspicious lines which are taken are: [352]
~~~~~~~~~~~~~~~~~~~~~~~~~~~~~~~~~~~~~~~~~~~~~~~~~~~~~~~~~~~~~~~~~~~~~~~~~~~~~~~~~~~~~~~~~~~~~~~~~~~~~~~
Start transforming line: 352
x Fail! Line: 352 could not be transformed: 'route = self.route_class('
~~~~~~~~~~~~~~~~~~~~~~~~~~~~~~~~~~~~~~~~~~~~~~~~~~~~~~~~~~~~~~~~~~~~~~~~~~~~~~~~~~~~~~~~~~~~~~~~~~~~~~~
Start creating 0 sketches.
✓
~~~~~~~~~~~~~~~~~~~~~~~~~~~~~~~~~~~~~~~~~~~~~~~~~~~~~~~~~~~~~~~~~~~~~~~~~~~~~~~~~~~~~~~~~~~~~~~~~~~~~~~
x Lines where no transformation is found:[352]
✓ Number of created sketches:0
Time needed: 0.02 minutes.

+*+*+*+*+*+*+*+*+*+*+*+*+*+*+*+*+*+*+*+*+*+*+*+*+*+*+*+*+*+*+*+*+*+*+*+*+*+*+*+*+*+*+*+*+*+*+*+*+*+*+*+

                                          BUG: 9

+*+*+*+*+*+*+*+*+*+*+*+*+*+*+*+*+*+*+*+*+*+*+*+*+*+*+*+*+*+*+*+*+*+*+*+*+*+*+*+*+*+*+*+*+*+*+*+*+*+*+*+
bug_file = /Users/daniel/BA_SketchFix_Evaluation/Evaluation/Projects/fastapi/fastapi/dependencies/utils.py
bug_test_file = /Users/daniel/BA_SketchFix_Evaluation/Evaluation/Projects/fastapi/tests/test_request_body_parameters_media_type.py
GIT RESET TO: a7a92bc63768ccee3f3afc2b73b2c581928dfe75
HEAD is now at a7a92bc :memo: Update release notes
TEST EXECUTION:
...........................
✓ SUCCESSFUL! TEST PASSES
✓ PyFix is started...

~~~~~~~~~~~~~~~~~~~~~~~~~~~~~~~~~~~~~~~~~~~~~~~~~~~~~~~~~~~~~~~~~~~~~~~~~~~~~~~~~~~~~~~~~~~~~~~~~~~~~~~

	                              PySketchFix®: Sketches are created.

~~~~~~~~~~~~~~~~~~~~~~~~~~~~~~~~~~~~~~~~~~~~~~~~~~~~~~~~~~~~~~~~~~~~~~~~~~~~~~~~~~~~~~~~~~~~~~~~~~~~~~~
PySketchFix will run with:
bug file: /Users/daniel/BA_SketchFix_Evaluation/Evaluation/Projects/fastapi/fastapi/dependencies/utils.py
~~~~~~~~~~~~~~~~~~~~~~~~~~~~~~~~~~~~~~~~~~~~~~~~~~~~~~~~~~~~~~~~~~~~~~~~~~~~~~~~~~~~~~~~~~~~~~~~~~~~~~~
The suspicious lines which are taken are: [577]
~~~~~~~~~~~~~~~~~~~~~~~~~~~~~~~~~~~~~~~~~~~~~~~~~~~~~~~~~~~~~~~~~~~~~~~~~~~~~~~~~~~~~~~~~~~~~~~~~~~~~~~
Start transforming line: 577

----------------------------------------------------------------------
Ran 0 tests in 0.000s

OK
✓
~~~~~~~~~~~~~~~~~~~~~~~~~~~~~~~~~~~~~~~~~~~~~~~~~~~~~~~~~~~~~~~~~~~~~~~~~~~~~~~~~~~~~~~~~~~~~~~~~~~~~~~
Start creating 1 sketches.
✓
~~~~~~~~~~~~~~~~~~~~~~~~~~~~~~~~~~~~~~~~~~~~~~~~~~~~~~~~~~~~~~~~~~~~~~~~~~~~~~~~~~~~~~~~~~~~~~~~~~~~~~~
x Lines where no transformation is found:[]
✓ Number of created sketches:1
Time needed: 0.04 minutes.

+*+*+*+*+*+*+*+*+*+*+*+*+*+*+*+*+*+*+*+*+*+*+*+*+*+*+*+*+*+*+*+*+*+*+*+*+*+*+*+*+*+*+*+*+*+*+*+*+*+*+*+

                                          BUG: 10

+*+*+*+*+*+*+*+*+*+*+*+*+*+*+*+*+*+*+*+*+*+*+*+*+*+*+*+*+*+*+*+*+*+*+*+*+*+*+*+*+*+*+*+*+*+*+*+*+*+*+*+
bug_file = /Users/daniel/BA_SketchFix_Evaluation/Evaluation/Projects/fastapi/fastapi/routing.py
bug_test_file = /Users/daniel/BA_SketchFix_Evaluation/Evaluation/Projects/fastapi/tests/test_skip_defaults.py
GIT RESET TO: b77a43bcac3ec8e7edbe82543e777c60ae85c178
HEAD is now at b77a43b :memo: Update release notes
TEST EXECUTION:

----------------------------------------------------------------------
Ran 0 tests in 0.000s

OK
...........................
✓ SUCCESSFUL! TEST PASSES
x FAIL! Suspicious lines are empty!

+*+*+*+*+*+*+*+*+*+*+*+*+*+*+*+*+*+*+*+*+*+*+*+*+*+*+*+*+*+*+*+*+*+*+*+*+*+*+*+*+*+*+*+*+*+*+*+*+*+*+*+

                                          BUG: 11

+*+*+*+*+*+*+*+*+*+*+*+*+*+*+*+*+*+*+*+*+*+*+*+*+*+*+*+*+*+*+*+*+*+*+*+*+*+*+*+*+*+*+*+*+*+*+*+*+*+*+*+
x FAIL! The bug test file: /Users/daniel/BA_SketchFix_Evaluation/Evaluation/Projects/fastapi/tests/test_union_body.py;tests/test_union_inherited_body.py to the project fastapi with bug: 11does not exists. Next bug is taken

+*+*+*+*+*+*+*+*+*+*+*+*+*+*+*+*+*+*+*+*+*+*+*+*+*+*+*+*+*+*+*+*+*+*+*+*+*+*+*+*+*+*+*+*+*+*+*+*+*+*+*+

                                          BUG: 12

+*+*+*+*+*+*+*+*+*+*+*+*+*+*+*+*+*+*+*+*+*+*+*+*+*+*+*+*+*+*+*+*+*+*+*+*+*+*+*+*+*+*+*+*+*+*+*+*+*+*+*+
bug_file = /Users/daniel/BA_SketchFix_Evaluation/Evaluation/Projects/fastapi/fastapi/security/http.py
bug_test_file = /Users/daniel/BA_SketchFix_Evaluation/Evaluation/Projects/fastapi/tests/test_security_http_bearer_optional.py
GIT RESET TO: d61f5e4b555b123bf222503fc0e076cbae6a7ebc
HEAD is now at d61f5e4 :memo: Update release notes
TEST EXECUTION:
...........................
x TEST FAILS
✓ PyFix is started...

~~~~~~~~~~~~~~~~~~~~~~~~~~~~~~~~~~~~~~~~~~~~~~~~~~~~~~~~~~~~~~~~~~~~~~~~~~~~~~~~~~~~~~~~~~~~~~~~~~~~~~~

	                              PySketchFix®: Sketches are created.

~~~~~~~~~~~~~~~~~~~~~~~~~~~~~~~~~~~~~~~~~~~~~~~~~~~~~~~~~~~~~~~~~~~~~~~~~~~~~~~~~~~~~~~~~~~~~~~~~~~~~~~
PySketchFix will run with:
bug file: /Users/daniel/BA_SketchFix_Evaluation/Evaluation/Projects/fastapi/fastapi/security/http.py
~~~~~~~~~~~~~~~~~~~~~~~~~~~~~~~~~~~~~~~~~~~~~~~~~~~~~~~~~~~~~~~~~~~~~~~~~~~~~~~~~~~~~~~~~~~~~~~~~~~~~~~
The suspicious lines which are taken are: [115, 116, 117, 118]
~~~~~~~~~~~~~~~~~~~~~~~~~~~~~~~~~~~~~~~~~~~~~~~~~~~~~~~~~~~~~~~~~~~~~~~~~~~~~~~~~~~~~~~~~~~~~~~~~~~~~~~
Start transforming line: 115
test_security_http_bearer_optional (unittest.loader._FailedTest) ... ERROR

======================================================================
ERROR: test_security_http_bearer_optional (unittest.loader._FailedTest)
----------------------------------------------------------------------
ImportError: Failed to import test module: test_security_http_bearer_optional
Traceback (most recent call last):
  File "/usr/local/Cellar/python/3.7.7/Frameworks/Python.framework/Versions/3.7/lib/python3.7/unittest/loader.py", line 436, in _find_test_path
    module = self._get_module_from_name(name)
  File "/usr/local/Cellar/python/3.7.7/Frameworks/Python.framework/Versions/3.7/lib/python3.7/unittest/loader.py", line 377, in _get_module_from_name
    __import__(name)
  File "/Users/daniel/BA_SketchFix_Evaluation/Evaluation/Projects/fastapi/tests/test_security_http_bearer_optional.py", line 3, in <module>
    from fastapi import FastAPI, Security
ModuleNotFoundError: No module named 'fastapi'


----------------------------------------------------------------------
Ran 1 test in 0.001s

FAILED (errors=1)
x Fail! Line: 115 could not be transformed: 'raise HTTPException('
Start transforming line: 116
✓
Start transforming line: 117
✓
Start transforming line: 118
x Fail! Line: 118 could not be transformed: ')'
~~~~~~~~~~~~~~~~~~~~~~~~~~~~~~~~~~~~~~~~~~~~~~~~~~~~~~~~~~~~~~~~~~~~~~~~~~~~~~~~~~~~~~~~~~~~~~~~~~~~~~~
Start creating 3 sketches.
✓
~~~~~~~~~~~~~~~~~~~~~~~~~~~~~~~~~~~~~~~~~~~~~~~~~~~~~~~~~~~~~~~~~~~~~~~~~~~~~~~~~~~~~~~~~~~~~~~~~~~~~~~
x Lines where no transformation is found:[115, 118]
✓ Number of created sketches:3
Time needed: 0.03 minutes.

+*+*+*+*+*+*+*+*+*+*+*+*+*+*+*+*+*+*+*+*+*+*+*+*+*+*+*+*+*+*+*+*+*+*+*+*+*+*+*+*+*+*+*+*+*+*+*+*+*+*+*+

                                          BUG: 13

+*+*+*+*+*+*+*+*+*+*+*+*+*+*+*+*+*+*+*+*+*+*+*+*+*+*+*+*+*+*+*+*+*+*+*+*+*+*+*+*+*+*+*+*+*+*+*+*+*+*+*+
bug_file = /Users/daniel/BA_SketchFix_Evaluation/Evaluation/Projects/fastapi/fastapi/routing.py
bug_test_file = /Users/daniel/BA_SketchFix_Evaluation/Evaluation/Projects/fastapi/tests/test_additional_responses_router.py
GIT RESET TO: 6f7f9268f6b03f42831dcfeaa5c15ba9813333ec
HEAD is now at 6f7f926 :memo: Update release notes
TEST EXECUTION:
...........................
✓ SUCCESSFUL! TEST PASSES
✓ PyFix is started...

~~~~~~~~~~~~~~~~~~~~~~~~~~~~~~~~~~~~~~~~~~~~~~~~~~~~~~~~~~~~~~~~~~~~~~~~~~~~~~~~~~~~~~~~~~~~~~~~~~~~~~~

	                              PySketchFix®: Sketches are created.

~~~~~~~~~~~~~~~~~~~~~~~~~~~~~~~~~~~~~~~~~~~~~~~~~~~~~~~~~~~~~~~~~~~~~~~~~~~~~~~~~~~~~~~~~~~~~~~~~~~~~~~
PySketchFix will run with:
bug file: /Users/daniel/BA_SketchFix_Evaluation/Evaluation/Projects/fastapi/fastapi/routing.py
~~~~~~~~~~~~~~~~~~~~~~~~~~~~~~~~~~~~~~~~~~~~~~~~~~~~~~~~~~~~~~~~~~~~~~~~~~~~~~~~~~~~~~~~~~~~~~~~~~~~~~~
The suspicious lines which are taken are: [290, 293, 294, 302]
~~~~~~~~~~~~~~~~~~~~~~~~~~~~~~~~~~~~~~~~~~~~~~~~~~~~~~~~~~~~~~~~~~~~~~~~~~~~~~~~~~~~~~~~~~~~~~~~~~~~~~~
Start transforming line: 290

----------------------------------------------------------------------
Ran 0 tests in 0.000s

OK
✓
Start transforming line: 293
x Fail! Line: 293 could not be transformed: 'self.add_api_route('
Start transforming line: 294
x Fail! Line: 294 could not be transformed: 'prefix + route.path,'
Start transforming line: 302
✓
~~~~~~~~~~~~~~~~~~~~~~~~~~~~~~~~~~~~~~~~~~~~~~~~~~~~~~~~~~~~~~~~~~~~~~~~~~~~~~~~~~~~~~~~~~~~~~~~~~~~~~~
Start creating 21 sketches.
✓
~~~~~~~~~~~~~~~~~~~~~~~~~~~~~~~~~~~~~~~~~~~~~~~~~~~~~~~~~~~~~~~~~~~~~~~~~~~~~~~~~~~~~~~~~~~~~~~~~~~~~~~
x Lines where no transformation is found:[293, 294]
✓ Number of created sketches:21
Time needed: 0.03 minutes.

+*+*+*+*+*+*+*+*+*+*+*+*+*+*+*+*+*+*+*+*+*+*+*+*+*+*+*+*+*+*+*+*+*+*+*+*+*+*+*+*+*+*+*+*+*+*+*+*+*+*+*+

                                          BUG: 14

+*+*+*+*+*+*+*+*+*+*+*+*+*+*+*+*+*+*+*+*+*+*+*+*+*+*+*+*+*+*+*+*+*+*+*+*+*+*+*+*+*+*+*+*+*+*+*+*+*+*+*+
bug_file = /Users/daniel/BA_SketchFix_Evaluation/Evaluation/Projects/fastapi/fastapi/openapi/models.py
bug_test_file = /Users/daniel/BA_SketchFix_Evaluation/Evaluation/Projects/fastapi/tests/test_additional_properties.py
GIT RESET TO: 2ddb804940bbcad4ed730b2a910c8fd3c1167127
HEAD is now at 2ddb804 :memo: Update release notes
TEST EXECUTION:

----------------------------------------------------------------------
Ran 0 tests in 0.000s

OK
...........................
✓ SUCCESSFUL! TEST PASSES
✓ PyFix is started...

~~~~~~~~~~~~~~~~~~~~~~~~~~~~~~~~~~~~~~~~~~~~~~~~~~~~~~~~~~~~~~~~~~~~~~~~~~~~~~~~~~~~~~~~~~~~~~~~~~~~~~~

	                              PySketchFix®: Sketches are created.

~~~~~~~~~~~~~~~~~~~~~~~~~~~~~~~~~~~~~~~~~~~~~~~~~~~~~~~~~~~~~~~~~~~~~~~~~~~~~~~~~~~~~~~~~~~~~~~~~~~~~~~
PySketchFix will run with:
bug file: /Users/daniel/BA_SketchFix_Evaluation/Evaluation/Projects/fastapi/fastapi/openapi/models.py
~~~~~~~~~~~~~~~~~~~~~~~~~~~~~~~~~~~~~~~~~~~~~~~~~~~~~~~~~~~~~~~~~~~~~~~~~~~~~~~~~~~~~~~~~~~~~~~~~~~~~~~
The suspicious lines which are taken are: [102, 123, 223]
~~~~~~~~~~~~~~~~~~~~~~~~~~~~~~~~~~~~~~~~~~~~~~~~~~~~~~~~~~~~~~~~~~~~~~~~~~~~~~~~~~~~~~~~~~~~~~~~~~~~~~~
Start transforming line: 102
x Fail! Line: 102 could not be transformed: 'additionalProperties Optional[Union[bool, Any]] = None'
Start transforming line: 123
x Fail! Line: 123 could not be transformed: 'additionalProperties Optional[Union[bool, SchemaBase]] = None'
Start transforming line: 223
x Fail! Line: 223 could not be transformed: 'responses Union[Responses, Dict[Union[str], Response]]'
~~~~~~~~~~~~~~~~~~~~~~~~~~~~~~~~~~~~~~~~~~~~~~~~~~~~~~~~~~~~~~~~~~~~~~~~~~~~~~~~~~~~~~~~~~~~~~~~~~~~~~~
Start creating 0 sketches.
✓
~~~~~~~~~~~~~~~~~~~~~~~~~~~~~~~~~~~~~~~~~~~~~~~~~~~~~~~~~~~~~~~~~~~~~~~~~~~~~~~~~~~~~~~~~~~~~~~~~~~~~~~
x Lines where no transformation is found:[102, 123, 223]
✓ Number of created sketches:0
Time needed: 0.01 minutes.

+*+*+*+*+*+*+*+*+*+*+*+*+*+*+*+*+*+*+*+*+*+*+*+*+*+*+*+*+*+*+*+*+*+*+*+*+*+*+*+*+*+*+*+*+*+*+*+*+*+*+*+

                                          BUG: 15

+*+*+*+*+*+*+*+*+*+*+*+*+*+*+*+*+*+*+*+*+*+*+*+*+*+*+*+*+*+*+*+*+*+*+*+*+*+*+*+*+*+*+*+*+*+*+*+*+*+*+*+
bug_file = /Users/daniel/BA_SketchFix_Evaluation/Evaluation/Projects/fastapi/fastapi/routing.py
bug_test_file = /Users/daniel/BA_SketchFix_Evaluation/Evaluation/Projects/fastapi/tests/test_ws_router.py
GIT RESET TO: b16ca54c30644667ab9f65a712704850666a039c
HEAD is now at b16ca54 :memo: Update Release Notes
TEST EXECUTION:
...........................
✓ SUCCESSFUL! TEST PASSES
x FAIL! Suspicious lines are empty!

+*+*+*+*+*+*+*+*+*+*+*+*+*+*+*+*+*+*+*+*+*+*+*+*+*+*+*+*+*+*+*+*+*+*+*+*+*+*+*+*+*+*+*+*+*+*+*+*+*+*+*+

                                          BUG: 16

+*+*+*+*+*+*+*+*+*+*+*+*+*+*+*+*+*+*+*+*+*+*+*+*+*+*+*+*+*+*+*+*+*+*+*+*+*+*+*+*+*+*+*+*+*+*+*+*+*+*+*+

----------------------------------------------------------------------
Ran 0 tests in 0.000s

OK
x FAIL! The bug test file: /Users/daniel/BA_SketchFix_Evaluation/Evaluation/Projects/fastapi/tests/test_datetime_custom_encoder.py;tests/test_jsonable_encoder.py to the project fastapi with bug: 16does not exists. Next bug is taken
#######################################################################################################
Results with bug numbers:
Project:fastapi
Failing:[1, 2, 7, 12]
Empty Sus Lines: [10, 15]
Passing[3, 4, 5, 6, 8, 9, 13, 14]

Process finished with exit code 0
