/Users/daniel/BA_SketchFix_Evaluation/Evaluation/venv/bin/python /Users/daniel/BA_SketchFix_Evaluation/Evaluation/SetupBug/replace_bug.py



#######################################################################################################
                             PROJECT: luigi
#######################################################################################################
CLONING PROJECT:
✓ SUCCESSFUL! This project is already cloned: https://github.com/spotify/luigi
The file: /Users/daniel/BA_SketchFix_Evaluation/Evaluation/BugsInPy/projects/luigi/bugs/2/bug_patch.txt in the project luigi does not exists. Next bug is taken
The file: /Users/daniel/BA_SketchFix_Evaluation/Evaluation/BugsInPy/projects/luigi/bugs/17/bug_patch.txt in the project luigi does not exists. Next bug is taken
The file: /Users/daniel/BA_SketchFix_Evaluation/Evaluation/BugsInPy/projects/luigi/bugs/20/bug_patch.txt in the project luigi does not exists. Next bug is taken
The file: /Users/daniel/BA_SketchFix_Evaluation/Evaluation/BugsInPy/projects/luigi/bugs/21/bug_patch.txt in the project luigi does not exists. Next bug is taken
The file: /Users/daniel/BA_SketchFix_Evaluation/Evaluation/BugsInPy/projects/luigi/bugs/24/bug_patch.txt in the project luigi does not exists. Next bug is taken
The file: /Users/daniel/BA_SketchFix_Evaluation/Evaluation/BugsInPy/projects/luigi/bugs/25/bug_patch.txt in the project luigi does not exists. Next bug is taken
.......................................................................................................
BUGGY LINES:
282,284
NF
1117,1118
356
281,285,286,288,293
824,862,863,864,865
826,827
335,339
46,49,53,90,380
305
897
43,44,45,46,47
91
93,95,202,203,213
485,486
570
NF
405
408
NF
NF
227
112,230
NF
NF
86
282,292,293,336,337
141
138,139,57,62,63
188,189,190,191,192
656

334
.......................................................................................................

+*+*+*+*+*+*+*+*+*+*+*+*+*+*+*+*+*+*+*+*+*+*+*+*+*+*+*+*+*+*+*+*+*+*+*+*+*+*+*+*+*+*+*+*+*+*+*+*+*+*+*+

                                          BUG: 1

+*+*+*+*+*+*+*+*+*+*+*+*+*+*+*+*+*+*+*+*+*+*+*+*+*+*+*+*+*+*+*+*+*+*+*+*+*+*+*+*+*+*+*+*+*+*+*+*+*+*+*+
GIT RESET TO: 1164eb6b85b8a70f596dbb99452bec513e72c12e
HEAD is now at 1164eb6b Version 2.8.5
bug_file = /Users/daniel/BA_SketchFix_Evaluation/Evaluation/Projects/luigi/luigi/server.py
bug_test_file = /Users/daniel/BA_SketchFix_Evaluation/Evaluation/Projects/luigi/test/server_test.py
TEST EXECUTION:
...........................
x TEST FAILS
✓ PyFix is started...

~~~~~~~~~~~~~~~~~~~~~~~~~~~~~~~~~~~~~~~~~~~~~~~~~~~~~~~~~~~~~~~~~~~~~~~~~~~~~~~~~~~~~~~~~~~~~~~~~~~~~~~

	                              PySketchFix®: Sketches are created.

~~~~~~~~~~~~~~~~~~~~~~~~~~~~~~~~~~~~~~~~~~~~~~~~~~~~~~~~~~~~~~~~~~~~~~~~~~~~~~~~~~~~~~~~~~~~~~~~~~~~~~~
PySketchFix will run with:
bug file: /Users/daniel/BA_SketchFix_Evaluation/Evaluation/Projects/luigi/luigi/server.py
~~~~~~~~~~~~~~~~~~~~~~~~~~~~~~~~~~~~~~~~~~~~~~~~~~~~~~~~~~~~~~~~~~~~~~~~~~~~~~~~~~~~~~~~~~~~~~~~~~~~~~~
The suspicious lines which are taken are: [282, 284]
~~~~~~~~~~~~~~~~~~~~~~~~~~~~~~~~~~~~~~~~~~~~~~~~~~~~~~~~~~~~~~~~~~~~~~~~~~~~~~~~~~~~~~~~~~~~~~~~~~~~~~~
Start transforming line: 282
auto_namespace_test (unittest.loader._FailedTest) ... ERROR
server_test (unittest.loader._FailedTest) ... ERROR

======================================================================
ERROR: auto_namespace_test (unittest.loader._FailedTest)
----------------------------------------------------------------------
ImportError: Failed to import test module: auto_namespace_test
Traceback (most recent call last):
  File "/usr/local/Cellar/python/3.7.7/Frameworks/Python.framework/Versions/3.7/lib/python3.7/unittest/loader.py", line 470, in _find_test_path
    package = self._get_module_from_name(name)
  File "/usr/local/Cellar/python/3.7.7/Frameworks/Python.framework/Versions/3.7/lib/python3.7/unittest/loader.py", line 377, in _get_module_from_name
    __import__(name)
  File "/Users/daniel/BA_SketchFix_Evaluation/Evaluation/Projects/luigi/test/auto_namespace_test/__init__.py", line 1, in <module>
    import luigi
ModuleNotFoundError: No module named 'luigi'


======================================================================
ERROR: server_test (unittest.loader._FailedTest)
----------------------------------------------------------------------
ImportError: Failed to import test module: server_test
Traceback (most recent call last):
  File "/usr/local/Cellar/python/3.7.7/Frameworks/Python.framework/Versions/3.7/lib/python3.7/unittest/loader.py", line 436, in _find_test_path
    module = self._get_module_from_name(name)
  File "/usr/local/Cellar/python/3.7.7/Frameworks/Python.framework/Versions/3.7/lib/python3.7/unittest/loader.py", line 377, in _get_module_from_name
    __import__(name)
  File "/Users/daniel/BA_SketchFix_Evaluation/Evaluation/Projects/luigi/test/server_test.py", line 24, in <module>
    from helpers import unittest, skipOnTravis
  File "/Users/daniel/BA_SketchFix_Evaluation/Evaluation/Projects/luigi/test/helpers.py", line 24, in <module>
    import luigi
ModuleNotFoundError: No module named 'luigi'


----------------------------------------------------------------------
Ran 2 tests in 0.001s

FAILED (errors=2)
x Fail! Line: 282 could not be transformed: 'metrics = self._scheduler._state._metrics_collector.generate_latest()'
Start transforming line: 284
✓
~~~~~~~~~~~~~~~~~~~~~~~~~~~~~~~~~~~~~~~~~~~~~~~~~~~~~~~~~~~~~~~~~~~~~~~~~~~~~~~~~~~~~~~~~~~~~~~~~~~~~~~
Start creating 2 sketches.
✓
~~~~~~~~~~~~~~~~~~~~~~~~~~~~~~~~~~~~~~~~~~~~~~~~~~~~~~~~~~~~~~~~~~~~~~~~~~~~~~~~~~~~~~~~~~~~~~~~~~~~~~~
x Lines where no transformation is found:[282]
✓ Number of created sketches:2
Time needed: 0.01 minutes.

+*+*+*+*+*+*+*+*+*+*+*+*+*+*+*+*+*+*+*+*+*+*+*+*+*+*+*+*+*+*+*+*+*+*+*+*+*+*+*+*+*+*+*+*+*+*+*+*+*+*+*+

                                          BUG: 3

+*+*+*+*+*+*+*+*+*+*+*+*+*+*+*+*+*+*+*+*+*+*+*+*+*+*+*+*+*+*+*+*+*+*+*+*+*+*+*+*+*+*+*+*+*+*+*+*+*+*+*+
GIT RESET TO: a0f1db01ddab5b4b2bda3fbe58bad09a6d94a7b4
HEAD is now at a0f1db01 Merge pull request #2626 from spotify/honnix-patch-1
bug_file = /Users/daniel/BA_SketchFix_Evaluation/Evaluation/Projects/luigi/luigi/parameter.py
bug_test_file = /Users/daniel/BA_SketchFix_Evaluation/Evaluation/Projects/luigi/test/parameter_test.py
TEST EXECUTION:
...........................
x TEST FAILS
✓ PyFix is started...

~~~~~~~~~~~~~~~~~~~~~~~~~~~~~~~~~~~~~~~~~~~~~~~~~~~~~~~~~~~~~~~~~~~~~~~~~~~~~~~~~~~~~~~~~~~~~~~~~~~~~~~

	                              PySketchFix®: Sketches are created.

~~~~~~~~~~~~~~~~~~~~~~~~~~~~~~~~~~~~~~~~~~~~~~~~~~~~~~~~~~~~~~~~~~~~~~~~~~~~~~~~~~~~~~~~~~~~~~~~~~~~~~~
PySketchFix will run with:
bug file: /Users/daniel/BA_SketchFix_Evaluation/Evaluation/Projects/luigi/luigi/parameter.py
~~~~~~~~~~~~~~~~~~~~~~~~~~~~~~~~~~~~~~~~~~~~~~~~~~~~~~~~~~~~~~~~~~~~~~~~~~~~~~~~~~~~~~~~~~~~~~~~~~~~~~~
The suspicious lines which are taken are: [1117, 1118]
~~~~~~~~~~~~~~~~~~~~~~~~~~~~~~~~~~~~~~~~~~~~~~~~~~~~~~~~~~~~~~~~~~~~~~~~~~~~~~~~~~~~~~~~~~~~~~~~~~~~~~~
Start transforming line: 1117
auto_namespace_test (unittest.loader._FailedTest) ... ERROR
parameter_test (unittest.loader._FailedTest) ... ERROR

======================================================================
ERROR: auto_namespace_test (unittest.loader._FailedTest)
----------------------------------------------------------------------
ImportError: Failed to import test module: auto_namespace_test
Traceback (most recent call last):
  File "/usr/local/Cellar/python/3.7.7/Frameworks/Python.framework/Versions/3.7/lib/python3.7/unittest/loader.py", line 470, in _find_test_path
    package = self._get_module_from_name(name)
  File "/usr/local/Cellar/python/3.7.7/Frameworks/Python.framework/Versions/3.7/lib/python3.7/unittest/loader.py", line 377, in _get_module_from_name
    __import__(name)
  File "/Users/daniel/BA_SketchFix_Evaluation/Evaluation/Projects/luigi/test/auto_namespace_test/__init__.py", line 1, in <module>
    import luigi
ModuleNotFoundError: No module named 'luigi'


======================================================================
ERROR: parameter_test (unittest.loader._FailedTest)
----------------------------------------------------------------------
ImportError: Failed to import test module: parameter_test
Traceback (most recent call last):
  File "/usr/local/Cellar/python/3.7.7/Frameworks/Python.framework/Versions/3.7/lib/python3.7/unittest/loader.py", line 436, in _find_test_path
    module = self._get_module_from_name(name)
  File "/usr/local/Cellar/python/3.7.7/Frameworks/Python.framework/Versions/3.7/lib/python3.7/unittest/loader.py", line 377, in _get_module_from_name
    __import__(name)
  File "/Users/daniel/BA_SketchFix_Evaluation/Evaluation/Projects/luigi/test/parameter_test.py", line 20, in <module>
    from helpers import with_config, LuigiTestCase, parsing, in_parse, RunOnceTask
  File "/Users/daniel/BA_SketchFix_Evaluation/Evaluation/Projects/luigi/test/helpers.py", line 24, in <module>
    import luigi
ModuleNotFoundError: No module named 'luigi'


----------------------------------------------------------------------
Ran 2 tests in 0.000s

FAILED (errors=2)
x Fail! Line: 1117 could not be transformed: 'except ValueError'
Start transforming line: 1118
✓
~~~~~~~~~~~~~~~~~~~~~~~~~~~~~~~~~~~~~~~~~~~~~~~~~~~~~~~~~~~~~~~~~~~~~~~~~~~~~~~~~~~~~~~~~~~~~~~~~~~~~~~
Start creating 2 sketches.
✓
~~~~~~~~~~~~~~~~~~~~~~~~~~~~~~~~~~~~~~~~~~~~~~~~~~~~~~~~~~~~~~~~~~~~~~~~~~~~~~~~~~~~~~~~~~~~~~~~~~~~~~~
x Lines where no transformation is found:[1117]
✓ Number of created sketches:2
Time needed: 0.01 minutes.

+*+*+*+*+*+*+*+*+*+*+*+*+*+*+*+*+*+*+*+*+*+*+*+*+*+*+*+*+*+*+*+*+*+*+*+*+*+*+*+*+*+*+*+*+*+*+*+*+*+*+*+

                                          BUG: 4

+*+*+*+*+*+*+*+*+*+*+*+*+*+*+*+*+*+*+*+*+*+*+*+*+*+*+*+*+*+*+*+*+*+*+*+*+*+*+*+*+*+*+*+*+*+*+*+*+*+*+*+
GIT RESET TO: ffa51b50103a3adaf3c4d0569fdb037a7ba01e8e
HEAD is now at ffa51b50 Support for AWS Batch (#2321)
bug_file = /Users/daniel/BA_SketchFix_Evaluation/Evaluation/Projects/luigi/luigi/contrib/redshift.py
bug_test_file = /Users/daniel/BA_SketchFix_Evaluation/Evaluation/Projects/luigi/test/contrib/redshift_test.py
TEST EXECUTION:
...........................
x TEST FAILS
✓ PyFix is started...

~~~~~~~~~~~~~~~~~~~~~~~~~~~~~~~~~~~~~~~~~~~~~~~~~~~~~~~~~~~~~~~~~~~~~~~~~~~~~~~~~~~~~~~~~~~~~~~~~~~~~~~

	                              PySketchFix®: Sketches are created.

~~~~~~~~~~~~~~~~~~~~~~~~~~~~~~~~~~~~~~~~~~~~~~~~~~~~~~~~~~~~~~~~~~~~~~~~~~~~~~~~~~~~~~~~~~~~~~~~~~~~~~~
PySketchFix will run with:
bug file: /Users/daniel/BA_SketchFix_Evaluation/Evaluation/Projects/luigi/luigi/contrib/redshift.py
~~~~~~~~~~~~~~~~~~~~~~~~~~~~~~~~~~~~~~~~~~~~~~~~~~~~~~~~~~~~~~~~~~~~~~~~~~~~~~~~~~~~~~~~~~~~~~~~~~~~~~~
The suspicious lines which are taken are: [356]
~~~~~~~~~~~~~~~~~~~~~~~~~~~~~~~~~~~~~~~~~~~~~~~~~~~~~~~~~~~~~~~~~~~~~~~~~~~~~~~~~~~~~~~~~~~~~~~~~~~~~~~
Start transforming line: 356
redshift_test (unittest.loader._FailedTest) ... ERROR

======================================================================
ERROR: redshift_test (unittest.loader._FailedTest)
----------------------------------------------------------------------
ImportError: Failed to import test module: redshift_test
Traceback (most recent call last):
  File "/usr/local/Cellar/python/3.7.7/Frameworks/Python.framework/Versions/3.7/lib/python3.7/unittest/loader.py", line 436, in _find_test_path
    module = self._get_module_from_name(name)
  File "/usr/local/Cellar/python/3.7.7/Frameworks/Python.framework/Versions/3.7/lib/python3.7/unittest/loader.py", line 377, in _get_module_from_name
    __import__(name)
  File "/Users/daniel/BA_SketchFix_Evaluation/Evaluation/Projects/luigi/test/contrib/redshift_test.py", line 15, in <module>
    import luigi
ModuleNotFoundError: No module named 'luigi'


----------------------------------------------------------------------
Ran 1 test in 0.000s

FAILED (errors=1)
✓
~~~~~~~~~~~~~~~~~~~~~~~~~~~~~~~~~~~~~~~~~~~~~~~~~~~~~~~~~~~~~~~~~~~~~~~~~~~~~~~~~~~~~~~~~~~~~~~~~~~~~~~
Start creating 24 sketches.
✓
~~~~~~~~~~~~~~~~~~~~~~~~~~~~~~~~~~~~~~~~~~~~~~~~~~~~~~~~~~~~~~~~~~~~~~~~~~~~~~~~~~~~~~~~~~~~~~~~~~~~~~~
x Lines where no transformation is found:[]
✓ Number of created sketches:24
Time needed: 0.0 minutes.

+*+*+*+*+*+*+*+*+*+*+*+*+*+*+*+*+*+*+*+*+*+*+*+*+*+*+*+*+*+*+*+*+*+*+*+*+*+*+*+*+*+*+*+*+*+*+*+*+*+*+*+

                                          BUG: 5

+*+*+*+*+*+*+*+*+*+*+*+*+*+*+*+*+*+*+*+*+*+*+*+*+*+*+*+*+*+*+*+*+*+*+*+*+*+*+*+*+*+*+*+*+*+*+*+*+*+*+*+
GIT RESET TO: 45b5711d1900184ccd66c65216d28c0d69d10d4a
HEAD is now at 45b5711d vizualiser: Format js code (#2309)
bug_file = /Users/daniel/BA_SketchFix_Evaluation/Evaluation/Projects/luigi/luigi/util.py
bug_test_file = /Users/daniel/BA_SketchFix_Evaluation/Evaluation/Projects/luigi/test/util_test.py
TEST EXECUTION:
...........................
x TEST FAILS
✓ PyFix is started...

~~~~~~~~~~~~~~~~~~~~~~~~~~~~~~~~~~~~~~~~~~~~~~~~~~~~~~~~~~~~~~~~~~~~~~~~~~~~~~~~~~~~~~~~~~~~~~~~~~~~~~~

	                              PySketchFix®: Sketches are created.

~~~~~~~~~~~~~~~~~~~~~~~~~~~~~~~~~~~~~~~~~~~~~~~~~~~~~~~~~~~~~~~~~~~~~~~~~~~~~~~~~~~~~~~~~~~~~~~~~~~~~~~
PySketchFix will run with:
bug file: /Users/daniel/BA_SketchFix_Evaluation/Evaluation/Projects/luigi/luigi/util.py
~~~~~~~~~~~~~~~~~~~~~~~~~~~~~~~~~~~~~~~~~~~~~~~~~~~~~~~~~~~~~~~~~~~~~~~~~~~~~~~~~~~~~~~~~~~~~~~~~~~~~~~
The suspicious lines which are taken are: [281, 285, 286, 288, 293]
~~~~~~~~~~~~~~~~~~~~~~~~~~~~~~~~~~~~~~~~~~~~~~~~~~~~~~~~~~~~~~~~~~~~~~~~~~~~~~~~~~~~~~~~~~~~~~~~~~~~~~~
Start transforming line: 281
auto_namespace_test (unittest.loader._FailedTest) ... ERROR
util_test (unittest.loader._FailedTest) ... ERROR

======================================================================
ERROR: auto_namespace_test (unittest.loader._FailedTest)
----------------------------------------------------------------------
ImportError: Failed to import test module: auto_namespace_test
Traceback (most recent call last):
  File "/usr/local/Cellar/python/3.7.7/Frameworks/Python.framework/Versions/3.7/lib/python3.7/unittest/loader.py", line 470, in _find_test_path
    package = self._get_module_from_name(name)
  File "/usr/local/Cellar/python/3.7.7/Frameworks/Python.framework/Versions/3.7/lib/python3.7/unittest/loader.py", line 377, in _get_module_from_name
    __import__(name)
  File "/Users/daniel/BA_SketchFix_Evaluation/Evaluation/Projects/luigi/test/auto_namespace_test/__init__.py", line 1, in <module>
    import luigi
ModuleNotFoundError: No module named 'luigi'


======================================================================
ERROR: util_test (unittest.loader._FailedTest)
----------------------------------------------------------------------
ImportError: Failed to import test module: util_test
Traceback (most recent call last):
  File "/usr/local/Cellar/python/3.7.7/Frameworks/Python.framework/Versions/3.7/lib/python3.7/unittest/loader.py", line 436, in _find_test_path
    module = self._get_module_from_name(name)
  File "/usr/local/Cellar/python/3.7.7/Frameworks/Python.framework/Versions/3.7/lib/python3.7/unittest/loader.py", line 377, in _get_module_from_name
    __import__(name)
  File "/Users/daniel/BA_SketchFix_Evaluation/Evaluation/Projects/luigi/test/util_test.py", line 17, in <module>
    from helpers import LuigiTestCase, RunOnceTask
  File "/Users/daniel/BA_SketchFix_Evaluation/Evaluation/Projects/luigi/test/helpers.py", line 24, in <module>
    import luigi
ModuleNotFoundError: No module named 'luigi'


----------------------------------------------------------------------
Ran 2 tests in 0.000s

FAILED (errors=2)
x Fail! Line: 281 could not be transformed: '   '
Start transforming line: 285
✓
Start transforming line: 286
✓
Start transforming line: 288
✓
Start transforming line: 293
x Fail! Line: 293 could not be transformed: 'Same as @inherits, but also auto-defines the requires method.'
~~~~~~~~~~~~~~~~~~~~~~~~~~~~~~~~~~~~~~~~~~~~~~~~~~~~~~~~~~~~~~~~~~~~~~~~~~~~~~~~~~~~~~~~~~~~~~~~~~~~~~~
Start creating 23 sketches.
✓
~~~~~~~~~~~~~~~~~~~~~~~~~~~~~~~~~~~~~~~~~~~~~~~~~~~~~~~~~~~~~~~~~~~~~~~~~~~~~~~~~~~~~~~~~~~~~~~~~~~~~~~
x Lines where no transformation is found:[281, 293]
✓ Number of created sketches:23
Time needed: 0.03 minutes.

+*+*+*+*+*+*+*+*+*+*+*+*+*+*+*+*+*+*+*+*+*+*+*+*+*+*+*+*+*+*+*+*+*+*+*+*+*+*+*+*+*+*+*+*+*+*+*+*+*+*+*+

                                          BUG: 6

+*+*+*+*+*+*+*+*+*+*+*+*+*+*+*+*+*+*+*+*+*+*+*+*+*+*+*+*+*+*+*+*+*+*+*+*+*+*+*+*+*+*+*+*+*+*+*+*+*+*+*+
GIT RESET TO: d9667b7c8ce75f17efa383e8f64e27e5852e6f89
HEAD is now at d9667b7c hivevar option in hive task (#2185)
bug_file = /Users/daniel/BA_SketchFix_Evaluation/Evaluation/Projects/luigi/luigi/parameter.py
bug_test_file = /Users/daniel/BA_SketchFix_Evaluation/Evaluation/Projects/luigi/test/parameter_test.py
TEST EXECUTION:
auto_namespace_test (unittest.loader._FailedTest) ... ERROR
parameter_test (unittest.loader._FailedTest) ... ERROR

======================================================================
ERROR: auto_namespace_test (unittest.loader._FailedTest)
----------------------------------------------------------------------
ImportError: Failed to import test module: auto_namespace_test
Traceback (most recent call last):
  File "/usr/local/Cellar/python/3.7.7/Frameworks/Python.framework/Versions/3.7/lib/python3.7/unittest/loader.py", line 470, in _find_test_path
    package = self._get_module_from_name(name)
  File "/usr/local/Cellar/python/3.7.7/Frameworks/Python.framework/Versions/3.7/lib/python3.7/unittest/loader.py", line 377, in _get_module_from_name
    __import__(name)
  File "/Users/daniel/BA_SketchFix_Evaluation/Evaluation/Projects/luigi/test/auto_namespace_test/__init__.py", line 1, in <module>
    import luigi
ModuleNotFoundError: No module named 'luigi'


======================================================================
ERROR: parameter_test (unittest.loader._FailedTest)
----------------------------------------------------------------------
ImportError: Failed to import test module: parameter_test
Traceback (most recent call last):
  File "/usr/local/Cellar/python/3.7.7/Frameworks/Python.framework/Versions/3.7/lib/python3.7/unittest/loader.py", line 436, in _find_test_path
    module = self._get_module_from_name(name)
  File "/usr/local/Cellar/python/3.7.7/Frameworks/Python.framework/Versions/3.7/lib/python3.7/unittest/loader.py", line 377, in _get_module_from_name
    __import__(name)
  File "/Users/daniel/BA_SketchFix_Evaluation/Evaluation/Projects/luigi/test/parameter_test.py", line 19, in <module>
    from helpers import with_config, LuigiTestCase, parsing, in_parse, RunOnceTask
  File "/Users/daniel/BA_SketchFix_Evaluation/Evaluation/Projects/luigi/test/helpers.py", line 24, in <module>
    import luigi
ModuleNotFoundError: No module named 'luigi'


----------------------------------------------------------------------
Ran 2 tests in 0.000s

FAILED (errors=2)
...........................
x TEST FAILS
✓ PyFix is started...

~~~~~~~~~~~~~~~~~~~~~~~~~~~~~~~~~~~~~~~~~~~~~~~~~~~~~~~~~~~~~~~~~~~~~~~~~~~~~~~~~~~~~~~~~~~~~~~~~~~~~~~

	                              PySketchFix®: Sketches are created.

~~~~~~~~~~~~~~~~~~~~~~~~~~~~~~~~~~~~~~~~~~~~~~~~~~~~~~~~~~~~~~~~~~~~~~~~~~~~~~~~~~~~~~~~~~~~~~~~~~~~~~~
PySketchFix will run with:
bug file: /Users/daniel/BA_SketchFix_Evaluation/Evaluation/Projects/luigi/luigi/parameter.py
~~~~~~~~~~~~~~~~~~~~~~~~~~~~~~~~~~~~~~~~~~~~~~~~~~~~~~~~~~~~~~~~~~~~~~~~~~~~~~~~~~~~~~~~~~~~~~~~~~~~~~~
The suspicious lines which are taken are: [824, 862, 863, 864, 865]
~~~~~~~~~~~~~~~~~~~~~~~~~~~~~~~~~~~~~~~~~~~~~~~~~~~~~~~~~~~~~~~~~~~~~~~~~~~~~~~~~~~~~~~~~~~~~~~~~~~~~~~
Start transforming line: 824
✓
Start transforming line: 862
x Fail! Line: 862 could not be transformed: 'class _DictParamEncoder(JSONEncoder)'
Start transforming line: 863
x Fail! Line: 863 could not be transformed: '"""'
Start transforming line: 864
x Fail! Line: 864 could not be transformed: 'JSON encoder pyclass`~DictParameter`, which makes pyclass`~_FrozenOrderedDict` JSON serializable.'
Start transforming line: 865
x Fail! Line: 865 could not be transformed: '"""'
~~~~~~~~~~~~~~~~~~~~~~~~~~~~~~~~~~~~~~~~~~~~~~~~~~~~~~~~~~~~~~~~~~~~~~~~~~~~~~~~~~~~~~~~~~~~~~~~~~~~~~~
Start creating 2 sketches.
✓
~~~~~~~~~~~~~~~~~~~~~~~~~~~~~~~~~~~~~~~~~~~~~~~~~~~~~~~~~~~~~~~~~~~~~~~~~~~~~~~~~~~~~~~~~~~~~~~~~~~~~~~
x Lines where no transformation is found:[862, 863, 864, 865]
✓ Number of created sketches:2
Time needed: 0.01 minutes.

+*+*+*+*+*+*+*+*+*+*+*+*+*+*+*+*+*+*+*+*+*+*+*+*+*+*+*+*+*+*+*+*+*+*+*+*+*+*+*+*+*+*+*+*+*+*+*+*+*+*+*+

                                          BUG: 7

+*+*+*+*+*+*+*+*+*+*+*+*+*+*+*+*+*+*+*+*+*+*+*+*+*+*+*+*+*+*+*+*+*+*+*+*+*+*+*+*+*+*+*+*+*+*+*+*+*+*+*+
GIT RESET TO: dd1f2ce0061e7787166522a3c75339ba4755dd2c
HEAD is now at dd1f2ce0 Update _get_s3_config to only return s3 section with interpolation, excluding defaults (#2182)
bug_file = /Users/daniel/BA_SketchFix_Evaluation/Evaluation/Projects/luigi/luigi/scheduler.py
bug_test_file = /Users/daniel/BA_SketchFix_Evaluation/Evaluation/Projects/luigi/test/scheduler_api_test.py
TEST EXECUTION:
...........................
x TEST FAILS
✓ PyFix is started...

~~~~~~~~~~~~~~~~~~~~~~~~~~~~~~~~~~~~~~~~~~~~~~~~~~~~~~~~~~~~~~~~~~~~~~~~~~~~~~~~~~~~~~~~~~~~~~~~~~~~~~~

	                              PySketchFix®: Sketches are created.

~~~~~~~~~~~~~~~~~~~~~~~~~~~~~~~~~~~~~~~~~~~~~~~~~~~~~~~~~~~~~~~~~~~~~~~~~~~~~~~~~~~~~~~~~~~~~~~~~~~~~~~
PySketchFix will run with:
bug file: /Users/daniel/BA_SketchFix_Evaluation/Evaluation/Projects/luigi/luigi/scheduler.py
~~~~~~~~~~~~~~~~~~~~~~~~~~~~~~~~~~~~~~~~~~~~~~~~~~~~~~~~~~~~~~~~~~~~~~~~~~~~~~~~~~~~~~~~~~~~~~~~~~~~~~~
The suspicious lines which are taken are: [826, 827]
~~~~~~~~~~~~~~~~~~~~~~~~~~~~~~~~~~~~~~~~~~~~~~~~~~~~~~~~~~~~~~~~~~~~~~~~~~~~~~~~~~~~~~~~~~~~~~~~~~~~~~~
Start transforming line: 826
auto_namespace_test (unittest.loader._FailedTest) ... ERROR
scheduler_api_test (unittest.loader._FailedTest) ... ERROR

======================================================================
ERROR: auto_namespace_test (unittest.loader._FailedTest)
----------------------------------------------------------------------
ImportError: Failed to import test module: auto_namespace_test
Traceback (most recent call last):
  File "/usr/local/Cellar/python/3.7.7/Frameworks/Python.framework/Versions/3.7/lib/python3.7/unittest/loader.py", line 470, in _find_test_path
    package = self._get_module_from_name(name)
  File "/usr/local/Cellar/python/3.7.7/Frameworks/Python.framework/Versions/3.7/lib/python3.7/unittest/loader.py", line 377, in _get_module_from_name
    __import__(name)
  File "/Users/daniel/BA_SketchFix_Evaluation/Evaluation/Projects/luigi/test/auto_namespace_test/__init__.py", line 1, in <module>
    import luigi
ModuleNotFoundError: No module named 'luigi'


======================================================================
ERROR: scheduler_api_test (unittest.loader._FailedTest)
----------------------------------------------------------------------
ImportError: Failed to import test module: scheduler_api_test
Traceback (most recent call last):
  File "/usr/local/Cellar/python/3.7.7/Frameworks/Python.framework/Versions/3.7/lib/python3.7/unittest/loader.py", line 436, in _find_test_path
    module = self._get_module_from_name(name)
  File "/usr/local/Cellar/python/3.7.7/Frameworks/Python.framework/Versions/3.7/lib/python3.7/unittest/loader.py", line 377, in _get_module_from_name
    __import__(name)
  File "/Users/daniel/BA_SketchFix_Evaluation/Evaluation/Projects/luigi/test/scheduler_api_test.py", line 19, in <module>
    import mock
ModuleNotFoundError: No module named 'mock'


----------------------------------------------------------------------
Ran 2 tests in 0.000s

FAILED (errors=2)
✓
Start transforming line: 827
x Fail! Line: 827 could not be transformed: '   '
~~~~~~~~~~~~~~~~~~~~~~~~~~~~~~~~~~~~~~~~~~~~~~~~~~~~~~~~~~~~~~~~~~~~~~~~~~~~~~~~~~~~~~~~~~~~~~~~~~~~~~~
Start creating 40 sketches.
✓
~~~~~~~~~~~~~~~~~~~~~~~~~~~~~~~~~~~~~~~~~~~~~~~~~~~~~~~~~~~~~~~~~~~~~~~~~~~~~~~~~~~~~~~~~~~~~~~~~~~~~~~
x Lines where no transformation is found:[827]
✓ Number of created sketches:40
Time needed: 0.01 minutes.

+*+*+*+*+*+*+*+*+*+*+*+*+*+*+*+*+*+*+*+*+*+*+*+*+*+*+*+*+*+*+*+*+*+*+*+*+*+*+*+*+*+*+*+*+*+*+*+*+*+*+*+

                                          BUG: 8

+*+*+*+*+*+*+*+*+*+*+*+*+*+*+*+*+*+*+*+*+*+*+*+*+*+*+*+*+*+*+*+*+*+*+*+*+*+*+*+*+*+*+*+*+*+*+*+*+*+*+*+
GIT RESET TO: 61ee32e9968978c32be12a6af0affa3a5750e87e
HEAD is now at 61ee32e9 Set datatable order correctly on hash change (#2159)
bug_file = /Users/daniel/BA_SketchFix_Evaluation/Evaluation/Projects/luigi/luigi/contrib/redshift.py
bug_test_file = /Users/daniel/BA_SketchFix_Evaluation/Evaluation/Projects/luigi/test/contrib/redshift_test.py
TEST EXECUTION:
...........................
x TEST FAILS
✓ PyFix is started...

~~~~~~~~~~~~~~~~~~~~~~~~~~~~~~~~~~~~~~~~~~~~~~~~~~~~~~~~~~~~~~~~~~~~~~~~~~~~~~~~~~~~~~~~~~~~~~~~~~~~~~~

	                              PySketchFix®: Sketches are created.

~~~~~~~~~~~~~~~~~~~~~~~~~~~~~~~~~~~~~~~~~~~~~~~~~~~~~~~~~~~~~~~~~~~~~~~~~~~~~~~~~~~~~~~~~~~~~~~~~~~~~~~
PySketchFix will run with:
bug file: /Users/daniel/BA_SketchFix_Evaluation/Evaluation/Projects/luigi/luigi/contrib/redshift.py
~~~~~~~~~~~~~~~~~~~~~~~~~~~~~~~~~~~~~~~~~~~~~~~~~~~~~~~~~~~~~~~~~~~~~~~~~~~~~~~~~~~~~~~~~~~~~~~~~~~~~~~
redshift_test (unittest.loader._FailedTest) ... ERROR

======================================================================
ERROR: redshift_test (unittest.loader._FailedTest)
----------------------------------------------------------------------
ImportError: Failed to import test module: redshift_test
Traceback (most recent call last):
  File "/usr/local/Cellar/python/3.7.7/Frameworks/Python.framework/Versions/3.7/lib/python3.7/unittest/loader.py", line 436, in _find_test_path
    module = self._get_module_from_name(name)
  File "/usr/local/Cellar/python/3.7.7/Frameworks/Python.framework/Versions/3.7/lib/python3.7/unittest/loader.py", line 377, in _get_module_from_name
    __import__(name)
  File "/Users/daniel/BA_SketchFix_Evaluation/Evaluation/Projects/luigi/test/contrib/redshift_test.py", line 15, in <module>
    import luigi
ModuleNotFoundError: No module named 'luigi'


----------------------------------------------------------------------
Ran 1 test in 0.000s

FAILED (errors=1)
The suspicious lines which are taken are: [335, 339]
~~~~~~~~~~~~~~~~~~~~~~~~~~~~~~~~~~~~~~~~~~~~~~~~~~~~~~~~~~~~~~~~~~~~~~~~~~~~~~~~~~~~~~~~~~~~~~~~~~~~~~~
Start transforming line: 335
x Fail! Line: 335 could not be transformed: ' "where table_schema = %s and table_name = %s limit 1")'
Start transforming line: 339
x Fail! Line: 339 could not be transformed: ' "where tablename = %s limit 1")'
~~~~~~~~~~~~~~~~~~~~~~~~~~~~~~~~~~~~~~~~~~~~~~~~~~~~~~~~~~~~~~~~~~~~~~~~~~~~~~~~~~~~~~~~~~~~~~~~~~~~~~~
Start creating 0 sketches.
✓
~~~~~~~~~~~~~~~~~~~~~~~~~~~~~~~~~~~~~~~~~~~~~~~~~~~~~~~~~~~~~~~~~~~~~~~~~~~~~~~~~~~~~~~~~~~~~~~~~~~~~~~
x Lines where no transformation is found:[335, 339]
✓ Number of created sketches:0
Time needed: 0.01 minutes.

+*+*+*+*+*+*+*+*+*+*+*+*+*+*+*+*+*+*+*+*+*+*+*+*+*+*+*+*+*+*+*+*+*+*+*+*+*+*+*+*+*+*+*+*+*+*+*+*+*+*+*+

                                          BUG: 9

+*+*+*+*+*+*+*+*+*+*+*+*+*+*+*+*+*+*+*+*+*+*+*+*+*+*+*+*+*+*+*+*+*+*+*+*+*+*+*+*+*+*+*+*+*+*+*+*+*+*+*+
GIT RESET TO: f7e0b7710fd8b12f27625b1efb62a8fde6e206c4
HEAD is now at f7e0b771 externalize: Dont register the copied tasks (#1975)
bug_file = /Users/daniel/BA_SketchFix_Evaluation/Evaluation/Projects/luigi/luigi/execution_summary.py
bug_test_file = /Users/daniel/BA_SketchFix_Evaluation/Evaluation/Projects/luigi/test/execution_summary_test.py
TEST EXECUTION:
execution_summary_test (unittest.loader._FailedTest) ... ERROR

======================================================================
ERROR: execution_summary_test (unittest.loader._FailedTest)
----------------------------------------------------------------------
ImportError: Failed to import test module: execution_summary_test
Traceback (most recent call last):
  File "/usr/local/Cellar/python/3.7.7/Frameworks/Python.framework/Versions/3.7/lib/python3.7/unittest/loader.py", line 436, in _find_test_path
    module = self._get_module_from_name(name)
  File "/usr/local/Cellar/python/3.7.7/Frameworks/Python.framework/Versions/3.7/lib/python3.7/unittest/loader.py", line 377, in _get_module_from_name
    __import__(name)
  File "/Users/daniel/BA_SketchFix_Evaluation/Evaluation/Projects/luigi/test/execution_summary_test.py", line 18, in <module>
    from helpers import LuigiTestCase, RunOnceTask, with_config
  File "/Users/daniel/BA_SketchFix_Evaluation/Evaluation/Projects/luigi/test/helpers.py", line 24, in <module>
    import luigi
ModuleNotFoundError: No module named 'luigi'


----------------------------------------------------------------------
Ran 1 test in 0.000s

FAILED (errors=1)
...........................
x TEST FAILS
✓ PyFix is started...

~~~~~~~~~~~~~~~~~~~~~~~~~~~~~~~~~~~~~~~~~~~~~~~~~~~~~~~~~~~~~~~~~~~~~~~~~~~~~~~~~~~~~~~~~~~~~~~~~~~~~~~

	                              PySketchFix®: Sketches are created.

~~~~~~~~~~~~~~~~~~~~~~~~~~~~~~~~~~~~~~~~~~~~~~~~~~~~~~~~~~~~~~~~~~~~~~~~~~~~~~~~~~~~~~~~~~~~~~~~~~~~~~~
PySketchFix will run with:
bug file: /Users/daniel/BA_SketchFix_Evaluation/Evaluation/Projects/luigi/luigi/execution_summary.py
~~~~~~~~~~~~~~~~~~~~~~~~~~~~~~~~~~~~~~~~~~~~~~~~~~~~~~~~~~~~~~~~~~~~~~~~~~~~~~~~~~~~~~~~~~~~~~~~~~~~~~~
The suspicious lines which are taken are: [46, 49, 53, 90, 380]
~~~~~~~~~~~~~~~~~~~~~~~~~~~~~~~~~~~~~~~~~~~~~~~~~~~~~~~~~~~~~~~~~~~~~~~~~~~~~~~~~~~~~~~~~~~~~~~~~~~~~~~
Start transforming line: 46
x Fail! Line: 46 could not be transformed: 'set_tasks["failed"] = {task (task, status, ext) in task_history status == 'FAILED'}'
Start transforming line: 49
x Fail! Line: 49 could not be transformed: '  status == 'PENDING' and task not in set_tasks["failed"] and task not in set_tasks["completed"] and not ext}'
Start transforming line: 53
x Fail! Line: 53 could not be transformed: 'set_tasks["upstream_failure"] = set()'
Start transforming line: 90
✓
Start transforming line: 380
x Fail! Line: 380 could not be transformed: 'set_tasks["failed"]'
~~~~~~~~~~~~~~~~~~~~~~~~~~~~~~~~~~~~~~~~~~~~~~~~~~~~~~~~~~~~~~~~~~~~~~~~~~~~~~~~~~~~~~~~~~~~~~~~~~~~~~~
Start creating 17 sketches.
✓
~~~~~~~~~~~~~~~~~~~~~~~~~~~~~~~~~~~~~~~~~~~~~~~~~~~~~~~~~~~~~~~~~~~~~~~~~~~~~~~~~~~~~~~~~~~~~~~~~~~~~~~
x Lines where no transformation is found:[46, 49, 53, 380]
✓ Number of created sketches:17
Time needed: 0.03 minutes.

+*+*+*+*+*+*+*+*+*+*+*+*+*+*+*+*+*+*+*+*+*+*+*+*+*+*+*+*+*+*+*+*+*+*+*+*+*+*+*+*+*+*+*+*+*+*+*+*+*+*+*+

                                          BUG: 10

+*+*+*+*+*+*+*+*+*+*+*+*+*+*+*+*+*+*+*+*+*+*+*+*+*+*+*+*+*+*+*+*+*+*+*+*+*+*+*+*+*+*+*+*+*+*+*+*+*+*+*+
GIT RESET TO: f538d1b3d473d542a19d508e5f7e0809b1dfe5ef
HEAD is now at f538d1b3 Sets upstream status for BATCH_RUNNING jobs to UPSTREAM_RUNNING (#1848)
bug_file = /Users/daniel/BA_SketchFix_Evaluation/Evaluation/Projects/luigi/luigi/scheduler.py
bug_test_file = /Users/daniel/BA_SketchFix_Evaluation/Evaluation/Projects/luigi/test/scheduler_test.py
TEST EXECUTION:
...........................
x TEST FAILS
✓ PyFix is started...

~~~~~~~~~~~~~~~~~~~~~~~~~~~~~~~~~~~~~~~~~~~~~~~~~~~~~~~~~~~~~~~~~~~~~~~~~~~~~~~~~~~~~~~~~~~~~~~~~~~~~~~

	                              PySketchFix®: Sketches are created.

~~~~~~~~~~~~~~~~~~~~~~~~~~~~~~~~~~~~~~~~~~~~~~~~~~~~~~~~~~~~~~~~~~~~~~~~~~~~~~~~~~~~~~~~~~~~~~~~~~~~~~~
PySketchFix will run with:
bug file: /Users/daniel/BA_SketchFix_Evaluation/Evaluation/Projects/luigi/luigi/scheduler.py
~~~~~~~~~~~~~~~~~~~~~~~~~~~~~~~~~~~~~~~~~~~~~~~~~~~~~~~~~~~~~~~~~~~~~~~~~~~~~~~~~~~~~~~~~~~~~~~~~~~~~~~
The suspicious lines which are taken are: [305]
~~~~~~~~~~~~~~~~~~~~~~~~~~~~~~~~~~~~~~~~~~~~~~~~~~~~~~~~~~~~~~~~~~~~~~~~~~~~~~~~~~~~~~~~~~~~~~~~~~~~~~~
Start transforming line: 305
scheduler_test (unittest.loader._FailedTest) ... ERROR

======================================================================
ERROR: scheduler_test (unittest.loader._FailedTest)
----------------------------------------------------------------------
ImportError: Failed to import test module: scheduler_test
Traceback (most recent call last):
  File "/usr/local/Cellar/python/3.7.7/Frameworks/Python.framework/Versions/3.7/lib/python3.7/unittest/loader.py", line 436, in _find_test_path
    module = self._get_module_from_name(name)
  File "/usr/local/Cellar/python/3.7.7/Frameworks/Python.framework/Versions/3.7/lib/python3.7/unittest/loader.py", line 377, in _get_module_from_name
    __import__(name)
  File "/Users/daniel/BA_SketchFix_Evaluation/Evaluation/Projects/luigi/test/scheduler_test.py", line 22, in <module>
    from helpers import unittest
  File "/Users/daniel/BA_SketchFix_Evaluation/Evaluation/Projects/luigi/test/helpers.py", line 24, in <module>
    import luigi
ModuleNotFoundError: No module named 'luigi'


----------------------------------------------------------------------
Ran 1 test in 0.000s

FAILED (errors=1)
x Fail! Line: 305 could not be transformed: 'return state.get_pending_tasks()'
~~~~~~~~~~~~~~~~~~~~~~~~~~~~~~~~~~~~~~~~~~~~~~~~~~~~~~~~~~~~~~~~~~~~~~~~~~~~~~~~~~~~~~~~~~~~~~~~~~~~~~~
Start creating 0 sketches.
✓
~~~~~~~~~~~~~~~~~~~~~~~~~~~~~~~~~~~~~~~~~~~~~~~~~~~~~~~~~~~~~~~~~~~~~~~~~~~~~~~~~~~~~~~~~~~~~~~~~~~~~~~
x Lines where no transformation is found:[305]
✓ Number of created sketches:0
Time needed: 0.01 minutes.

+*+*+*+*+*+*+*+*+*+*+*+*+*+*+*+*+*+*+*+*+*+*+*+*+*+*+*+*+*+*+*+*+*+*+*+*+*+*+*+*+*+*+*+*+*+*+*+*+*+*+*+

                                          BUG: 11

+*+*+*+*+*+*+*+*+*+*+*+*+*+*+*+*+*+*+*+*+*+*+*+*+*+*+*+*+*+*+*+*+*+*+*+*+*+*+*+*+*+*+*+*+*+*+*+*+*+*+*+
GIT RESET TO: bf8b5cba573d5d6cd11f7f10a03b458aeaf955c1
HEAD is now at bf8b5cba dataproc tests: Attempt to fix failing build (#1843)
bug_file = /Users/daniel/BA_SketchFix_Evaluation/Evaluation/Projects/luigi/luigi/scheduler.py
bug_test_file = /Users/daniel/BA_SketchFix_Evaluation/Evaluation/Projects/luigi/test/scheduler_api_test.py
TEST EXECUTION:
scheduler_api_test (unittest.loader._FailedTest) ... ERROR

======================================================================
ERROR: scheduler_api_test (unittest.loader._FailedTest)
----------------------------------------------------------------------
ImportError: Failed to import test module: scheduler_api_test
Traceback (most recent call last):
  File "/usr/local/Cellar/python/3.7.7/Frameworks/Python.framework/Versions/3.7/lib/python3.7/unittest/loader.py", line 436, in _find_test_path
    module = self._get_module_from_name(name)
  File "/usr/local/Cellar/python/3.7.7/Frameworks/Python.framework/Versions/3.7/lib/python3.7/unittest/loader.py", line 377, in _get_module_from_name
    __import__(name)
  File "/Users/daniel/BA_SketchFix_Evaluation/Evaluation/Projects/luigi/test/scheduler_api_test.py", line 20, in <module>
    from helpers import unittest
  File "/Users/daniel/BA_SketchFix_Evaluation/Evaluation/Projects/luigi/test/helpers.py", line 24, in <module>
    import luigi
ModuleNotFoundError: No module named 'luigi'


----------------------------------------------------------------------
Ran 1 test in 0.000s

FAILED (errors=1)
...........................
x TEST FAILS
✓ PyFix is started...

~~~~~~~~~~~~~~~~~~~~~~~~~~~~~~~~~~~~~~~~~~~~~~~~~~~~~~~~~~~~~~~~~~~~~~~~~~~~~~~~~~~~~~~~~~~~~~~~~~~~~~~

	                              PySketchFix®: Sketches are created.

~~~~~~~~~~~~~~~~~~~~~~~~~~~~~~~~~~~~~~~~~~~~~~~~~~~~~~~~~~~~~~~~~~~~~~~~~~~~~~~~~~~~~~~~~~~~~~~~~~~~~~~
PySketchFix will run with:
bug file: /Users/daniel/BA_SketchFix_Evaluation/Evaluation/Projects/luigi/luigi/scheduler.py
~~~~~~~~~~~~~~~~~~~~~~~~~~~~~~~~~~~~~~~~~~~~~~~~~~~~~~~~~~~~~~~~~~~~~~~~~~~~~~~~~~~~~~~~~~~~~~~~~~~~~~~
The suspicious lines which are taken are: [897]
~~~~~~~~~~~~~~~~~~~~~~~~~~~~~~~~~~~~~~~~~~~~~~~~~~~~~~~~~~~~~~~~~~~~~~~~~~~~~~~~~~~~~~~~~~~~~~~~~~~~~~~
Start transforming line: 897
x Fail! Line: 897 could not be transformed: 'task.params.get(name) == value name, value in unbatched_params.items()))'
~~~~~~~~~~~~~~~~~~~~~~~~~~~~~~~~~~~~~~~~~~~~~~~~~~~~~~~~~~~~~~~~~~~~~~~~~~~~~~~~~~~~~~~~~~~~~~~~~~~~~~~
Start creating 0 sketches.
✓
~~~~~~~~~~~~~~~~~~~~~~~~~~~~~~~~~~~~~~~~~~~~~~~~~~~~~~~~~~~~~~~~~~~~~~~~~~~~~~~~~~~~~~~~~~~~~~~~~~~~~~~
x Lines where no transformation is found:[897]
✓ Number of created sketches:0
Time needed: 0.0 minutes.

+*+*+*+*+*+*+*+*+*+*+*+*+*+*+*+*+*+*+*+*+*+*+*+*+*+*+*+*+*+*+*+*+*+*+*+*+*+*+*+*+*+*+*+*+*+*+*+*+*+*+*+

                                          BUG: 12

+*+*+*+*+*+*+*+*+*+*+*+*+*+*+*+*+*+*+*+*+*+*+*+*+*+*+*+*+*+*+*+*+*+*+*+*+*+*+*+*+*+*+*+*+*+*+*+*+*+*+*+
GIT RESET TO: c3119757c9ad4141fb446554109fa09cbd31173c
HEAD is now at c3119757 Add additional event handlers to tasks (#1698)
x FAIL! The bug test file: /Users/daniel/BA_SketchFix_Evaluation/Evaluation/Projects/luigi/test/hdfs_client_test.py to the project luigi with bug: 12does not exists. Next bug is taken

+*+*+*+*+*+*+*+*+*+*+*+*+*+*+*+*+*+*+*+*+*+*+*+*+*+*+*+*+*+*+*+*+*+*+*+*+*+*+*+*+*+*+*+*+*+*+*+*+*+*+*+

                                          BUG: 13

+*+*+*+*+*+*+*+*+*+*+*+*+*+*+*+*+*+*+*+*+*+*+*+*+*+*+*+*+*+*+*+*+*+*+*+*+*+*+*+*+*+*+*+*+*+*+*+*+*+*+*+
GIT RESET TO: 3c90bcdac63d978dbdaeae408420e22b963c9863
HEAD is now at 3c90bcda Changed task_history_override to task_history_impl (#1641)
bug_file = /Users/daniel/BA_SketchFix_Evaluation/Evaluation/Projects/luigi/luigi/file.py
bug_test_file = /Users/daniel/BA_SketchFix_Evaluation/Evaluation/Projects/luigi/test/file_test.py
TEST EXECUTION:
file_test (unittest.loader._FailedTest) ... ERROR

======================================================================
ERROR: file_test (unittest.loader._FailedTest)
----------------------------------------------------------------------
ImportError: Failed to import test module: file_test
Traceback (most recent call last):
  File "/usr/local/Cellar/python/3.7.7/Frameworks/Python.framework/Versions/3.7/lib/python3.7/unittest/loader.py", line 436, in _find_test_path
    module = self._get_module_from_name(name)
  File "/usr/local/Cellar/python/3.7.7/Frameworks/Python.framework/Versions/3.7/lib/python3.7/unittest/loader.py", line 377, in _get_module_from_name
    __import__(name)
  File "/Users/daniel/BA_SketchFix_Evaluation/Evaluation/Projects/luigi/test/file_test.py", line 24, in <module>
    from helpers import unittest
  File "/Users/daniel/BA_SketchFix_Evaluation/Evaluation/Projects/luigi/test/helpers.py", line 21, in <module>
    import luigi
ModuleNotFoundError: No module named 'luigi'


----------------------------------------------------------------------
Ran 1 test in 0.000s

FAILED (errors=1)
...........................
x TEST FAILS
✓ PyFix is started...

~~~~~~~~~~~~~~~~~~~~~~~~~~~~~~~~~~~~~~~~~~~~~~~~~~~~~~~~~~~~~~~~~~~~~~~~~~~~~~~~~~~~~~~~~~~~~~~~~~~~~~~

	                              PySketchFix®: Sketches are created.

~~~~~~~~~~~~~~~~~~~~~~~~~~~~~~~~~~~~~~~~~~~~~~~~~~~~~~~~~~~~~~~~~~~~~~~~~~~~~~~~~~~~~~~~~~~~~~~~~~~~~~~
PySketchFix will run with:
bug file: /Users/daniel/BA_SketchFix_Evaluation/Evaluation/Projects/luigi/luigi/file.py
~~~~~~~~~~~~~~~~~~~~~~~~~~~~~~~~~~~~~~~~~~~~~~~~~~~~~~~~~~~~~~~~~~~~~~~~~~~~~~~~~~~~~~~~~~~~~~~~~~~~~~~
The suspicious lines which are taken are: [91]
~~~~~~~~~~~~~~~~~~~~~~~~~~~~~~~~~~~~~~~~~~~~~~~~~~~~~~~~~~~~~~~~~~~~~~~~~~~~~~~~~~~~~~~~~~~~~~~~~~~~~~~
Start transforming line: 91
✓
~~~~~~~~~~~~~~~~~~~~~~~~~~~~~~~~~~~~~~~~~~~~~~~~~~~~~~~~~~~~~~~~~~~~~~~~~~~~~~~~~~~~~~~~~~~~~~~~~~~~~~~
Start creating 3 sketches.
✓
~~~~~~~~~~~~~~~~~~~~~~~~~~~~~~~~~~~~~~~~~~~~~~~~~~~~~~~~~~~~~~~~~~~~~~~~~~~~~~~~~~~~~~~~~~~~~~~~~~~~~~~
x Lines where no transformation is found:[]
✓ Number of created sketches:3
Time needed: 0.0 minutes.

+*+*+*+*+*+*+*+*+*+*+*+*+*+*+*+*+*+*+*+*+*+*+*+*+*+*+*+*+*+*+*+*+*+*+*+*+*+*+*+*+*+*+*+*+*+*+*+*+*+*+*+

                                          BUG: 14

+*+*+*+*+*+*+*+*+*+*+*+*+*+*+*+*+*+*+*+*+*+*+*+*+*+*+*+*+*+*+*+*+*+*+*+*+*+*+*+*+*+*+*+*+*+*+*+*+*+*+*+
GIT RESET TO: f7219c38121098d464011a094156d99b5b320362
HEAD is now at f7219c38 Add status message endpoints to RPC handler list.
bug_file = /Users/daniel/BA_SketchFix_Evaluation/Evaluation/Projects/luigi/luigi/scheduler.py
bug_test_file = /Users/daniel/BA_SketchFix_Evaluation/Evaluation/Projects/luigi/test/central_planner_test.py
TEST EXECUTION:
central_planner_test (unittest.loader._FailedTest) ... ERROR

======================================================================
ERROR: central_planner_test (unittest.loader._FailedTest)
----------------------------------------------------------------------
ImportError: Failed to import test module: central_planner_test
Traceback (most recent call last):
  File "/usr/local/Cellar/python/3.7.7/Frameworks/Python.framework/Versions/3.7/lib/python3.7/unittest/loader.py", line 436, in _find_test_path
    module = self._get_module_from_name(name)
  File "/usr/local/Cellar/python/3.7.7/Frameworks/Python.framework/Versions/3.7/lib/python3.7/unittest/loader.py", line 377, in _get_module_from_name
    __import__(name)
  File "/Users/daniel/BA_SketchFix_Evaluation/Evaluation/Projects/luigi/test/central_planner_test.py", line 19, in <module>
    from helpers import unittest
  File "/Users/daniel/BA_SketchFix_Evaluation/Evaluation/Projects/luigi/test/helpers.py", line 21, in <module>
    import luigi
ModuleNotFoundError: No module named 'luigi'


----------------------------------------------------------------------
Ran 1 test in 0.000s

FAILED (errors=1)
...........................
x TEST FAILS
✓ PyFix is started...

~~~~~~~~~~~~~~~~~~~~~~~~~~~~~~~~~~~~~~~~~~~~~~~~~~~~~~~~~~~~~~~~~~~~~~~~~~~~~~~~~~~~~~~~~~~~~~~~~~~~~~~

	                              PySketchFix®: Sketches are created.

~~~~~~~~~~~~~~~~~~~~~~~~~~~~~~~~~~~~~~~~~~~~~~~~~~~~~~~~~~~~~~~~~~~~~~~~~~~~~~~~~~~~~~~~~~~~~~~~~~~~~~~
PySketchFix will run with:
bug file: /Users/daniel/BA_SketchFix_Evaluation/Evaluation/Projects/luigi/luigi/scheduler.py
~~~~~~~~~~~~~~~~~~~~~~~~~~~~~~~~~~~~~~~~~~~~~~~~~~~~~~~~~~~~~~~~~~~~~~~~~~~~~~~~~~~~~~~~~~~~~~~~~~~~~~~
The suspicious lines which are taken are: [93, 95, 202, 203, 213]
~~~~~~~~~~~~~~~~~~~~~~~~~~~~~~~~~~~~~~~~~~~~~~~~~~~~~~~~~~~~~~~~~~~~~~~~~~~~~~~~~~~~~~~~~~~~~~~~~~~~~~~
Start transforming line: 93
x Fail! Line: 93 could not be transformed: 'disable_failures = parameter.IntParameter(default=None,'
Start transforming line: 95
x Fail! Line: 95 could not be transformed: 'disable_hard_timeout = parameter.IntParameter(default=None,'
Start transforming line: 202
x Fail! Line: 202 could not be transformed: '(self.failures.first_failure_time is not None and'
Start transforming line: 203
x Fail! Line: 203 could not be transformed: 'self.disable_hard_timeout)'
Start transforming line: 213
✓
~~~~~~~~~~~~~~~~~~~~~~~~~~~~~~~~~~~~~~~~~~~~~~~~~~~~~~~~~~~~~~~~~~~~~~~~~~~~~~~~~~~~~~~~~~~~~~~~~~~~~~~
Start creating 3 sketches.
✓
~~~~~~~~~~~~~~~~~~~~~~~~~~~~~~~~~~~~~~~~~~~~~~~~~~~~~~~~~~~~~~~~~~~~~~~~~~~~~~~~~~~~~~~~~~~~~~~~~~~~~~~
x Lines where no transformation is found:[93, 95, 202, 203]
✓ Number of created sketches:3
Time needed: 0.02 minutes.

+*+*+*+*+*+*+*+*+*+*+*+*+*+*+*+*+*+*+*+*+*+*+*+*+*+*+*+*+*+*+*+*+*+*+*+*+*+*+*+*+*+*+*+*+*+*+*+*+*+*+*+

                                          BUG: 15

+*+*+*+*+*+*+*+*+*+*+*+*+*+*+*+*+*+*+*+*+*+*+*+*+*+*+*+*+*+*+*+*+*+*+*+*+*+*+*+*+*+*+*+*+*+*+*+*+*+*+*+
GIT RESET TO: a822f55d4d7c5adf5b9e3b64f23189d8305e9bf9
HEAD is now at a822f55d Scheduler: Refactor and bugfix task pruning
bug_file = /Users/daniel/BA_SketchFix_Evaluation/Evaluation/Projects/luigi/luigi/scheduler.py
bug_test_file = /Users/daniel/BA_SketchFix_Evaluation/Evaluation/Projects/luigi/test/central_planner_test.py
TEST EXECUTION:
central_planner_test (unittest.loader._FailedTest) ... ERROR

======================================================================
ERROR: central_planner_test (unittest.loader._FailedTest)
----------------------------------------------------------------------
ImportError: Failed to import test module: central_planner_test
Traceback (most recent call last):
  File "/usr/local/Cellar/python/3.7.7/Frameworks/Python.framework/Versions/3.7/lib/python3.7/unittest/loader.py", line 436, in _find_test_path
    module = self._get_module_from_name(name)
  File "/usr/local/Cellar/python/3.7.7/Frameworks/Python.framework/Versions/3.7/lib/python3.7/unittest/loader.py", line 377, in _get_module_from_name
    __import__(name)
  File "/Users/daniel/BA_SketchFix_Evaluation/Evaluation/Projects/luigi/test/central_planner_test.py", line 19, in <module>
    from helpers import unittest
  File "/Users/daniel/BA_SketchFix_Evaluation/Evaluation/Projects/luigi/test/helpers.py", line 21, in <module>
    import luigi
ModuleNotFoundError: No module named 'luigi'


----------------------------------------------------------------------
Ran 1 test in 0.000s

FAILED (errors=1)
...........................
x TEST FAILS
✓ PyFix is started...

~~~~~~~~~~~~~~~~~~~~~~~~~~~~~~~~~~~~~~~~~~~~~~~~~~~~~~~~~~~~~~~~~~~~~~~~~~~~~~~~~~~~~~~~~~~~~~~~~~~~~~~

	                              PySketchFix®: Sketches are created.

~~~~~~~~~~~~~~~~~~~~~~~~~~~~~~~~~~~~~~~~~~~~~~~~~~~~~~~~~~~~~~~~~~~~~~~~~~~~~~~~~~~~~~~~~~~~~~~~~~~~~~~
PySketchFix will run with:
bug file: /Users/daniel/BA_SketchFix_Evaluation/Evaluation/Projects/luigi/luigi/scheduler.py
~~~~~~~~~~~~~~~~~~~~~~~~~~~~~~~~~~~~~~~~~~~~~~~~~~~~~~~~~~~~~~~~~~~~~~~~~~~~~~~~~~~~~~~~~~~~~~~~~~~~~~~
The suspicious lines which are taken are: [485, 486]
~~~~~~~~~~~~~~~~~~~~~~~~~~~~~~~~~~~~~~~~~~~~~~~~~~~~~~~~~~~~~~~~~~~~~~~~~~~~~~~~~~~~~~~~~~~~~~~~~~~~~~~
Start transforming line: 485
x Fail! Line: 485 could not be transformed: 'task.status not in (DONE, DISABLED) or \'
Start transforming line: 486
✓
~~~~~~~~~~~~~~~~~~~~~~~~~~~~~~~~~~~~~~~~~~~~~~~~~~~~~~~~~~~~~~~~~~~~~~~~~~~~~~~~~~~~~~~~~~~~~~~~~~~~~~~
Start creating 17 sketches.
✓
~~~~~~~~~~~~~~~~~~~~~~~~~~~~~~~~~~~~~~~~~~~~~~~~~~~~~~~~~~~~~~~~~~~~~~~~~~~~~~~~~~~~~~~~~~~~~~~~~~~~~~~
x Lines where no transformation is found:[485]
✓ Number of created sketches:17
Time needed: 0.01 minutes.

+*+*+*+*+*+*+*+*+*+*+*+*+*+*+*+*+*+*+*+*+*+*+*+*+*+*+*+*+*+*+*+*+*+*+*+*+*+*+*+*+*+*+*+*+*+*+*+*+*+*+*+

                                          BUG: 16

+*+*+*+*+*+*+*+*+*+*+*+*+*+*+*+*+*+*+*+*+*+*+*+*+*+*+*+*+*+*+*+*+*+*+*+*+*+*+*+*+*+*+*+*+*+*+*+*+*+*+*+
GIT RESET TO: e38392a1381dd8daee0f180f0ac7f651edb88e0c
HEAD is now at e38392a1 Merge pull request #1497 from riga/fixLocalSchedTaskHist
bug_file = /Users/daniel/BA_SketchFix_Evaluation/Evaluation/Projects/luigi/luigi/scheduler.py
bug_test_file = /Users/daniel/BA_SketchFix_Evaluation/Evaluation/Projects/luigi/test/central_planner_test.py
TEST EXECUTION:
...........................
x TEST FAILS
✓ PyFix is started...

~~~~~~~~~~~~~~~~~~~~~~~~~~~~~~~~~~~~~~~~~~~~~~~~~~~~~~~~~~~~~~~~~~~~~~~~~~~~~~~~~~~~~~~~~~~~~~~~~~~~~~~

	                              PySketchFix®: Sketches are created.

~~~~~~~~~~~~~~~~~~~~~~~~~~~~~~~~~~~~~~~~~~~~~~~~~~~~~~~~~~~~~~~~~~~~~~~~~~~~~~~~~~~~~~~~~~~~~~~~~~~~~~~
PySketchFix will run with:
bug file: /Users/daniel/BA_SketchFix_Evaluation/Evaluation/Projects/luigi/luigi/scheduler.py
~~~~~~~~~~~~~~~~~~~~~~~~~~~~~~~~~~~~~~~~~~~~~~~~~~~~~~~~~~~~~~~~~~~~~~~~~~~~~~~~~~~~~~~~~~~~~~~~~~~~~~~
central_planner_test (unittest.loader._FailedTest) ... ERROR

======================================================================
ERROR: central_planner_test (unittest.loader._FailedTest)
----------------------------------------------------------------------
ImportError: Failed to import test module: central_planner_test
Traceback (most recent call last):
  File "/usr/local/Cellar/python/3.7.7/Frameworks/Python.framework/Versions/3.7/lib/python3.7/unittest/loader.py", line 436, in _find_test_path
    module = self._get_module_from_name(name)
  File "/usr/local/Cellar/python/3.7.7/Frameworks/Python.framework/Versions/3.7/lib/python3.7/unittest/loader.py", line 377, in _get_module_from_name
    __import__(name)
  File "/Users/daniel/BA_SketchFix_Evaluation/Evaluation/Projects/luigi/test/central_planner_test.py", line 19, in <module>
    from helpers import unittest
  File "/Users/daniel/BA_SketchFix_Evaluation/Evaluation/Projects/luigi/test/helpers.py", line 21, in <module>
    import luigi
ModuleNotFoundError: No module named 'luigi'


----------------------------------------------------------------------
Ran 1 test in 0.000s

FAILED (errors=1)
The suspicious lines which are taken are: [570]
~~~~~~~~~~~~~~~~~~~~~~~~~~~~~~~~~~~~~~~~~~~~~~~~~~~~~~~~~~~~~~~~~~~~~~~~~~~~~~~~~~~~~~~~~~~~~~~~~~~~~~~
Start transforming line: 570
✓
~~~~~~~~~~~~~~~~~~~~~~~~~~~~~~~~~~~~~~~~~~~~~~~~~~~~~~~~~~~~~~~~~~~~~~~~~~~~~~~~~~~~~~~~~~~~~~~~~~~~~~~
Start creating 29 sketches.
✓
~~~~~~~~~~~~~~~~~~~~~~~~~~~~~~~~~~~~~~~~~~~~~~~~~~~~~~~~~~~~~~~~~~~~~~~~~~~~~~~~~~~~~~~~~~~~~~~~~~~~~~~
x Lines where no transformation is found:[]
✓ Number of created sketches:29
Time needed: 0.01 minutes.

+*+*+*+*+*+*+*+*+*+*+*+*+*+*+*+*+*+*+*+*+*+*+*+*+*+*+*+*+*+*+*+*+*+*+*+*+*+*+*+*+*+*+*+*+*+*+*+*+*+*+*+

                                          BUG: 18

+*+*+*+*+*+*+*+*+*+*+*+*+*+*+*+*+*+*+*+*+*+*+*+*+*+*+*+*+*+*+*+*+*+*+*+*+*+*+*+*+*+*+*+*+*+*+*+*+*+*+*+
GIT RESET TO: 6cffbf438d023441f7f42c2019a51c62eecd9018
HEAD is now at 6cffbf43 Fixes a bug with auto-reenable when disable_failures is 1
bug_file = /Users/daniel/BA_SketchFix_Evaluation/Evaluation/Projects/luigi/luigi/scheduler.py
bug_test_file = /Users/daniel/BA_SketchFix_Evaluation/Evaluation/Projects/luigi/test/central_planner_test.py
TEST EXECUTION:
central_planner_test (unittest.loader._FailedTest) ... ERROR

======================================================================
ERROR: central_planner_test (unittest.loader._FailedTest)
----------------------------------------------------------------------
ImportError: Failed to import test module: central_planner_test
Traceback (most recent call last):
  File "/usr/local/Cellar/python/3.7.7/Frameworks/Python.framework/Versions/3.7/lib/python3.7/unittest/loader.py", line 436, in _find_test_path
    module = self._get_module_from_name(name)
  File "/usr/local/Cellar/python/3.7.7/Frameworks/Python.framework/Versions/3.7/lib/python3.7/unittest/loader.py", line 377, in _get_module_from_name
    __import__(name)
  File "/Users/daniel/BA_SketchFix_Evaluation/Evaluation/Projects/luigi/test/central_planner_test.py", line 19, in <module>
    from helpers import unittest
  File "/Users/daniel/BA_SketchFix_Evaluation/Evaluation/Projects/luigi/test/helpers.py", line 21, in <module>
    import luigi
ModuleNotFoundError: No module named 'luigi'


----------------------------------------------------------------------
Ran 1 test in 0.000s

FAILED (errors=1)
...........................
x TEST FAILS
✓ PyFix is started...

~~~~~~~~~~~~~~~~~~~~~~~~~~~~~~~~~~~~~~~~~~~~~~~~~~~~~~~~~~~~~~~~~~~~~~~~~~~~~~~~~~~~~~~~~~~~~~~~~~~~~~~

	                              PySketchFix®: Sketches are created.

~~~~~~~~~~~~~~~~~~~~~~~~~~~~~~~~~~~~~~~~~~~~~~~~~~~~~~~~~~~~~~~~~~~~~~~~~~~~~~~~~~~~~~~~~~~~~~~~~~~~~~~
PySketchFix will run with:
bug file: /Users/daniel/BA_SketchFix_Evaluation/Evaluation/Projects/luigi/luigi/scheduler.py
~~~~~~~~~~~~~~~~~~~~~~~~~~~~~~~~~~~~~~~~~~~~~~~~~~~~~~~~~~~~~~~~~~~~~~~~~~~~~~~~~~~~~~~~~~~~~~~~~~~~~~~
The suspicious lines which are taken are: [405]
~~~~~~~~~~~~~~~~~~~~~~~~~~~~~~~~~~~~~~~~~~~~~~~~~~~~~~~~~~~~~~~~~~~~~~~~~~~~~~~~~~~~~~~~~~~~~~~~~~~~~~~
Start transforming line: 405
✓
~~~~~~~~~~~~~~~~~~~~~~~~~~~~~~~~~~~~~~~~~~~~~~~~~~~~~~~~~~~~~~~~~~~~~~~~~~~~~~~~~~~~~~~~~~~~~~~~~~~~~~~
Start creating 18 sketches.
✓
~~~~~~~~~~~~~~~~~~~~~~~~~~~~~~~~~~~~~~~~~~~~~~~~~~~~~~~~~~~~~~~~~~~~~~~~~~~~~~~~~~~~~~~~~~~~~~~~~~~~~~~
x Lines where no transformation is found:[]
✓ Number of created sketches:18
Time needed: 0.0 minutes.

+*+*+*+*+*+*+*+*+*+*+*+*+*+*+*+*+*+*+*+*+*+*+*+*+*+*+*+*+*+*+*+*+*+*+*+*+*+*+*+*+*+*+*+*+*+*+*+*+*+*+*+

                                          BUG: 19

+*+*+*+*+*+*+*+*+*+*+*+*+*+*+*+*+*+*+*+*+*+*+*+*+*+*+*+*+*+*+*+*+*+*+*+*+*+*+*+*+*+*+*+*+*+*+*+*+*+*+*+
GIT RESET TO: 3d2f75224c7649402927a5ef57558d8c3717cd94
HEAD is now at 3d2f7522 Check that scheduler_disable_time is not None before re-enables
bug_file = /Users/daniel/BA_SketchFix_Evaluation/Evaluation/Projects/luigi/luigi/scheduler.py
bug_test_file = /Users/daniel/BA_SketchFix_Evaluation/Evaluation/Projects/luigi/test/central_planner_test.py
TEST EXECUTION:
central_planner_test (unittest.loader._FailedTest) ... ERROR

======================================================================
ERROR: central_planner_test (unittest.loader._FailedTest)
----------------------------------------------------------------------
ImportError: Failed to import test module: central_planner_test
Traceback (most recent call last):
  File "/usr/local/Cellar/python/3.7.7/Frameworks/Python.framework/Versions/3.7/lib/python3.7/unittest/loader.py", line 436, in _find_test_path
    module = self._get_module_from_name(name)
  File "/usr/local/Cellar/python/3.7.7/Frameworks/Python.framework/Versions/3.7/lib/python3.7/unittest/loader.py", line 377, in _get_module_from_name
    __import__(name)
  File "/Users/daniel/BA_SketchFix_Evaluation/Evaluation/Projects/luigi/test/central_planner_test.py", line 19, in <module>
    from helpers import unittest
  File "/Users/daniel/BA_SketchFix_Evaluation/Evaluation/Projects/luigi/test/helpers.py", line 21, in <module>
    import luigi
ModuleNotFoundError: No module named 'luigi'


----------------------------------------------------------------------
Ran 1 test in 0.000s

FAILED (errors=1)
...........................
x TEST FAILS
✓ PyFix is started...

~~~~~~~~~~~~~~~~~~~~~~~~~~~~~~~~~~~~~~~~~~~~~~~~~~~~~~~~~~~~~~~~~~~~~~~~~~~~~~~~~~~~~~~~~~~~~~~~~~~~~~~

	                              PySketchFix®: Sketches are created.

~~~~~~~~~~~~~~~~~~~~~~~~~~~~~~~~~~~~~~~~~~~~~~~~~~~~~~~~~~~~~~~~~~~~~~~~~~~~~~~~~~~~~~~~~~~~~~~~~~~~~~~
PySketchFix will run with:
bug file: /Users/daniel/BA_SketchFix_Evaluation/Evaluation/Projects/luigi/luigi/scheduler.py
~~~~~~~~~~~~~~~~~~~~~~~~~~~~~~~~~~~~~~~~~~~~~~~~~~~~~~~~~~~~~~~~~~~~~~~~~~~~~~~~~~~~~~~~~~~~~~~~~~~~~~~
The suspicious lines which are taken are: [408]
~~~~~~~~~~~~~~~~~~~~~~~~~~~~~~~~~~~~~~~~~~~~~~~~~~~~~~~~~~~~~~~~~~~~~~~~~~~~~~~~~~~~~~~~~~~~~~~~~~~~~~~
Start transforming line: 408
✓
~~~~~~~~~~~~~~~~~~~~~~~~~~~~~~~~~~~~~~~~~~~~~~~~~~~~~~~~~~~~~~~~~~~~~~~~~~~~~~~~~~~~~~~~~~~~~~~~~~~~~~~
Start creating 14 sketches.
✓
~~~~~~~~~~~~~~~~~~~~~~~~~~~~~~~~~~~~~~~~~~~~~~~~~~~~~~~~~~~~~~~~~~~~~~~~~~~~~~~~~~~~~~~~~~~~~~~~~~~~~~~
x Lines where no transformation is found:[]
✓ Number of created sketches:14
Time needed: 0.01 minutes.

+*+*+*+*+*+*+*+*+*+*+*+*+*+*+*+*+*+*+*+*+*+*+*+*+*+*+*+*+*+*+*+*+*+*+*+*+*+*+*+*+*+*+*+*+*+*+*+*+*+*+*+

                                          BUG: 22

+*+*+*+*+*+*+*+*+*+*+*+*+*+*+*+*+*+*+*+*+*+*+*+*+*+*+*+*+*+*+*+*+*+*+*+*+*+*+*+*+*+*+*+*+*+*+*+*+*+*+*+
GIT RESET TO: 9c4c47ae449593c55fb67ce51115d0be1fecb163
HEAD is now at 9c4c47ae Merge pull request #1002 from vine/bq
bug_file = /Users/daniel/BA_SketchFix_Evaluation/Evaluation/Projects/luigi/luigi/scheduler.py
bug_test_file = /Users/daniel/BA_SketchFix_Evaluation/Evaluation/Projects/luigi/test/scheduler_test.py
TEST EXECUTION:
...........................
x TEST FAILS
✓ PyFix is started...

~~~~~~~~~~~~~~~~~~~~~~~~~~~~~~~~~~~~~~~~~~~~~~~~~~~~~~~~~~~~~~~~~~~~~~~~~~~~~~~~~~~~~~~~~~~~~~~~~~~~~~~

	                              PySketchFix®: Sketches are created.

~~~~~~~~~~~~~~~~~~~~~~~~~~~~~~~~~~~~~~~~~~~~~~~~~~~~~~~~~~~~~~~~~~~~~~~~~~~~~~~~~~~~~~~~~~~~~~~~~~~~~~~
PySketchFix will run with:
bug file: /Users/daniel/BA_SketchFix_Evaluation/Evaluation/Projects/luigi/luigi/scheduler.py
~~~~~~~~~~~~~~~~~~~~~~~~~~~~~~~~~~~~~~~~~~~~~~~~~~~~~~~~~~~~~~~~~~~~~~~~~~~~~~~~~~~~~~~~~~~~~~~~~~~~~~~
scheduler_test (unittest.loader._FailedTest) ... ERROR

======================================================================
ERROR: scheduler_test (unittest.loader._FailedTest)
----------------------------------------------------------------------
ImportError: Failed to import test module: scheduler_test
Traceback (most recent call last):
  File "/usr/local/Cellar/python/3.7.7/Frameworks/Python.framework/Versions/3.7/lib/python3.7/unittest/loader.py", line 436, in _find_test_path
    module = self._get_module_from_name(name)
  File "/usr/local/Cellar/python/3.7.7/Frameworks/Python.framework/Versions/3.7/lib/python3.7/unittest/loader.py", line 377, in _get_module_from_name
    __import__(name)
  File "/Users/daniel/BA_SketchFix_Evaluation/Evaluation/Projects/luigi/test/scheduler_test.py", line 22, in <module>
    from helpers import unittest
  File "/Users/daniel/BA_SketchFix_Evaluation/Evaluation/Projects/luigi/test/helpers.py", line 22, in <module>
    import luigi
ModuleNotFoundError: No module named 'luigi'


----------------------------------------------------------------------
Ran 1 test in 0.001s

FAILED (errors=1)
The suspicious lines which are taken are: [227]
~~~~~~~~~~~~~~~~~~~~~~~~~~~~~~~~~~~~~~~~~~~~~~~~~~~~~~~~~~~~~~~~~~~~~~~~~~~~~~~~~~~~~~~~~~~~~~~~~~~~~~~
Start transforming line: 227
✓
~~~~~~~~~~~~~~~~~~~~~~~~~~~~~~~~~~~~~~~~~~~~~~~~~~~~~~~~~~~~~~~~~~~~~~~~~~~~~~~~~~~~~~~~~~~~~~~~~~~~~~~
Start creating 3 sketches.
✓
~~~~~~~~~~~~~~~~~~~~~~~~~~~~~~~~~~~~~~~~~~~~~~~~~~~~~~~~~~~~~~~~~~~~~~~~~~~~~~~~~~~~~~~~~~~~~~~~~~~~~~~
x Lines where no transformation is found:[]
✓ Number of created sketches:3
Time needed: 0.01 minutes.

+*+*+*+*+*+*+*+*+*+*+*+*+*+*+*+*+*+*+*+*+*+*+*+*+*+*+*+*+*+*+*+*+*+*+*+*+*+*+*+*+*+*+*+*+*+*+*+*+*+*+*+

                                          BUG: 23

+*+*+*+*+*+*+*+*+*+*+*+*+*+*+*+*+*+*+*+*+*+*+*+*+*+*+*+*+*+*+*+*+*+*+*+*+*+*+*+*+*+*+*+*+*+*+*+*+*+*+*+
GIT RESET TO: c707253572deb795a900c3e07d21eee591a55fca
HEAD is now at c7072535 Merge pull request #1033 from spotify/Tarrasch-patch-1
bug_file = /Users/daniel/BA_SketchFix_Evaluation/Evaluation/Projects/luigi/luigi/interface.py
bug_test_file = /Users/daniel/BA_SketchFix_Evaluation/Evaluation/Projects/luigi/test/worker_external_task_test.py
TEST EXECUTION:
worker_external_task_test (unittest.loader._FailedTest) ... ERROR

======================================================================
ERROR: worker_external_task_test (unittest.loader._FailedTest)
----------------------------------------------------------------------
ImportError: Failed to import test module: worker_external_task_test
Traceback (most recent call last):
  File "/usr/local/Cellar/python/3.7.7/Frameworks/Python.framework/Versions/3.7/lib/python3.7/unittest/loader.py", line 436, in _find_test_path
    module = self._get_module_from_name(name)
  File "/usr/local/Cellar/python/3.7.7/Frameworks/Python.framework/Versions/3.7/lib/python3.7/unittest/loader.py", line 377, in _get_module_from_name
    __import__(name)
  File "/Users/daniel/BA_SketchFix_Evaluation/Evaluation/Projects/luigi/test/worker_external_task_test.py", line 15, in <module>
    import luigi
ModuleNotFoundError: No module named 'luigi'


----------------------------------------------------------------------
Ran 1 test in 0.000s

FAILED (errors=1)
...........................
x TEST FAILS
✓ PyFix is started...

~~~~~~~~~~~~~~~~~~~~~~~~~~~~~~~~~~~~~~~~~~~~~~~~~~~~~~~~~~~~~~~~~~~~~~~~~~~~~~~~~~~~~~~~~~~~~~~~~~~~~~~

	                              PySketchFix®: Sketches are created.

~~~~~~~~~~~~~~~~~~~~~~~~~~~~~~~~~~~~~~~~~~~~~~~~~~~~~~~~~~~~~~~~~~~~~~~~~~~~~~~~~~~~~~~~~~~~~~~~~~~~~~~
PySketchFix will run with:
bug file: /Users/daniel/BA_SketchFix_Evaluation/Evaluation/Projects/luigi/luigi/interface.py
~~~~~~~~~~~~~~~~~~~~~~~~~~~~~~~~~~~~~~~~~~~~~~~~~~~~~~~~~~~~~~~~~~~~~~~~~~~~~~~~~~~~~~~~~~~~~~~~~~~~~~~
The suspicious lines which are taken are: [112, 230]
~~~~~~~~~~~~~~~~~~~~~~~~~~~~~~~~~~~~~~~~~~~~~~~~~~~~~~~~~~~~~~~~~~~~~~~~~~~~~~~~~~~~~~~~~~~~~~~~~~~~~~~
Start transforming line: 112
x Fail! Line: 112 could not be transformed: 'return scheduler.CentralPlannerScheduler()'
Start transforming line: 230
x Fail! Line: 230 could not be transformed: 'params = {}'
~~~~~~~~~~~~~~~~~~~~~~~~~~~~~~~~~~~~~~~~~~~~~~~~~~~~~~~~~~~~~~~~~~~~~~~~~~~~~~~~~~~~~~~~~~~~~~~~~~~~~~~
Start creating 0 sketches.
✓
~~~~~~~~~~~~~~~~~~~~~~~~~~~~~~~~~~~~~~~~~~~~~~~~~~~~~~~~~~~~~~~~~~~~~~~~~~~~~~~~~~~~~~~~~~~~~~~~~~~~~~~
x Lines where no transformation is found:[112, 230]
✓ Number of created sketches:0
Time needed: 0.01 minutes.

+*+*+*+*+*+*+*+*+*+*+*+*+*+*+*+*+*+*+*+*+*+*+*+*+*+*+*+*+*+*+*+*+*+*+*+*+*+*+*+*+*+*+*+*+*+*+*+*+*+*+*+

                                          BUG: 26

+*+*+*+*+*+*+*+*+*+*+*+*+*+*+*+*+*+*+*+*+*+*+*+*+*+*+*+*+*+*+*+*+*+*+*+*+*+*+*+*+*+*+*+*+*+*+*+*+*+*+*+
GIT RESET TO: ed351ca3c3baf3657de584db08dfe0414fa000a3
HEAD is now at ed351ca3 Add custom error, and use str.format()
x FAIL! The bug test file: /Users/daniel/BA_SketchFix_Evaluation/Evaluation/Projects/luigi/test/contrib/hadoop_jar_test.py to the project luigi with bug: 26does not exists. Next bug is taken

+*+*+*+*+*+*+*+*+*+*+*+*+*+*+*+*+*+*+*+*+*+*+*+*+*+*+*+*+*+*+*+*+*+*+*+*+*+*+*+*+*+*+*+*+*+*+*+*+*+*+*+

                                          BUG: 27

+*+*+*+*+*+*+*+*+*+*+*+*+*+*+*+*+*+*+*+*+*+*+*+*+*+*+*+*+*+*+*+*+*+*+*+*+*+*+*+*+*+*+*+*+*+*+*+*+*+*+*+
GIT RESET TO: 69dfec33dc7c34d551ddc71742fa9c847295b01f
HEAD is now at 69dfec33 Merge pull request #956 from Houzz/snakebite_cascading
bug_file = /Users/daniel/BA_SketchFix_Evaluation/Evaluation/Projects/luigi/luigi/parameter.py
bug_test_file = /Users/daniel/BA_SketchFix_Evaluation/Evaluation/Projects/luigi/test/parameter_test.py
TEST EXECUTION:
parameter_test (unittest.loader._FailedTest) ... ERROR

======================================================================
ERROR: parameter_test (unittest.loader._FailedTest)
----------------------------------------------------------------------
ImportError: Failed to import test module: parameter_test
Traceback (most recent call last):
  File "/usr/local/Cellar/python/3.7.7/Frameworks/Python.framework/Versions/3.7/lib/python3.7/unittest/loader.py", line 436, in _find_test_path
    module = self._get_module_from_name(name)
  File "/usr/local/Cellar/python/3.7.7/Frameworks/Python.framework/Versions/3.7/lib/python3.7/unittest/loader.py", line 377, in _get_module_from_name
    __import__(name)
  File "/Users/daniel/BA_SketchFix_Evaluation/Evaluation/Projects/luigi/test/parameter_test.py", line 19, in <module>
    from helpers import unittest
  File "/Users/daniel/BA_SketchFix_Evaluation/Evaluation/Projects/luigi/test/helpers.py", line 22, in <module>
    from luigi import six
ModuleNotFoundError: No module named 'luigi'


----------------------------------------------------------------------
Ran 1 test in 0.000s

FAILED (errors=1)
...........................
x TEST FAILS
✓ PyFix is started...

~~~~~~~~~~~~~~~~~~~~~~~~~~~~~~~~~~~~~~~~~~~~~~~~~~~~~~~~~~~~~~~~~~~~~~~~~~~~~~~~~~~~~~~~~~~~~~~~~~~~~~~

	                              PySketchFix®: Sketches are created.

~~~~~~~~~~~~~~~~~~~~~~~~~~~~~~~~~~~~~~~~~~~~~~~~~~~~~~~~~~~~~~~~~~~~~~~~~~~~~~~~~~~~~~~~~~~~~~~~~~~~~~~
PySketchFix will run with:
bug file: /Users/daniel/BA_SketchFix_Evaluation/Evaluation/Projects/luigi/luigi/parameter.py
~~~~~~~~~~~~~~~~~~~~~~~~~~~~~~~~~~~~~~~~~~~~~~~~~~~~~~~~~~~~~~~~~~~~~~~~~~~~~~~~~~~~~~~~~~~~~~~~~~~~~~~
The suspicious lines which are taken are: [282, 292, 293, 336, 337]
~~~~~~~~~~~~~~~~~~~~~~~~~~~~~~~~~~~~~~~~~~~~~~~~~~~~~~~~~~~~~~~~~~~~~~~~~~~~~~~~~~~~~~~~~~~~~~~~~~~~~~~
Start transforming line: 282
✓
Start transforming line: 292
✓
Start transforming line: 293
✓
Start transforming line: 336
✓
Start transforming line: 337
✓
~~~~~~~~~~~~~~~~~~~~~~~~~~~~~~~~~~~~~~~~~~~~~~~~~~~~~~~~~~~~~~~~~~~~~~~~~~~~~~~~~~~~~~~~~~~~~~~~~~~~~~~
Start creating 199 sketches.
✓
~~~~~~~~~~~~~~~~~~~~~~~~~~~~~~~~~~~~~~~~~~~~~~~~~~~~~~~~~~~~~~~~~~~~~~~~~~~~~~~~~~~~~~~~~~~~~~~~~~~~~~~
x Lines where no transformation is found:[]
✓ Number of created sketches:199
Time needed: 0.03 minutes.

+*+*+*+*+*+*+*+*+*+*+*+*+*+*+*+*+*+*+*+*+*+*+*+*+*+*+*+*+*+*+*+*+*+*+*+*+*+*+*+*+*+*+*+*+*+*+*+*+*+*+*+

                                          BUG: 28

+*+*+*+*+*+*+*+*+*+*+*+*+*+*+*+*+*+*+*+*+*+*+*+*+*+*+*+*+*+*+*+*+*+*+*+*+*+*+*+*+*+*+*+*+*+*+*+*+*+*+*+
GIT RESET TO: e37cb0ea1d97e6340840128a68c8d59bd05c28c3
HEAD is now at e37cb0ea Merge pull request #893 from kutschkem/kutschkem-patch-891-pathseparator
bug_file = /Users/daniel/BA_SketchFix_Evaluation/Evaluation/Projects/luigi/luigi/contrib/hive.py
bug_test_file = /Users/daniel/BA_SketchFix_Evaluation/Evaluation/Projects/luigi/test/contrib/hive_test.py
TEST EXECUTION:
hive_test (unittest.loader._FailedTest) ... ERROR

======================================================================
ERROR: hive_test (unittest.loader._FailedTest)
----------------------------------------------------------------------
ImportError: Failed to import test module: hive_test
Traceback (most recent call last):
  File "/usr/local/Cellar/python/3.7.7/Frameworks/Python.framework/Versions/3.7/lib/python3.7/unittest/loader.py", line 436, in _find_test_path
    module = self._get_module_from_name(name)
  File "/usr/local/Cellar/python/3.7.7/Frameworks/Python.framework/Versions/3.7/lib/python3.7/unittest/loader.py", line 377, in _get_module_from_name
    __import__(name)
  File "/Users/daniel/BA_SketchFix_Evaluation/Evaluation/Projects/luigi/test/contrib/hive_test.py", line 25, in <module>
    from helpers import unittest
  File "/Users/daniel/BA_SketchFix_Evaluation/Evaluation/Projects/luigi/test/helpers.py", line 21, in <module>
    from luigi import six
ModuleNotFoundError: No module named 'luigi'


----------------------------------------------------------------------
Ran 1 test in 0.000s

FAILED (errors=1)
...........................
x TEST FAILS
✓ PyFix is started...

~~~~~~~~~~~~~~~~~~~~~~~~~~~~~~~~~~~~~~~~~~~~~~~~~~~~~~~~~~~~~~~~~~~~~~~~~~~~~~~~~~~~~~~~~~~~~~~~~~~~~~~

	                              PySketchFix®: Sketches are created.

~~~~~~~~~~~~~~~~~~~~~~~~~~~~~~~~~~~~~~~~~~~~~~~~~~~~~~~~~~~~~~~~~~~~~~~~~~~~~~~~~~~~~~~~~~~~~~~~~~~~~~~
PySketchFix will run with:
bug file: /Users/daniel/BA_SketchFix_Evaluation/Evaluation/Projects/luigi/luigi/contrib/hive.py
~~~~~~~~~~~~~~~~~~~~~~~~~~~~~~~~~~~~~~~~~~~~~~~~~~~~~~~~~~~~~~~~~~~~~~~~~~~~~~~~~~~~~~~~~~~~~~~~~~~~~~~
The suspicious lines which are taken are: [141]
~~~~~~~~~~~~~~~~~~~~~~~~~~~~~~~~~~~~~~~~~~~~~~~~~~~~~~~~~~~~~~~~~~~~~~~~~~~~~~~~~~~~~~~~~~~~~~~~~~~~~~~
Start transforming line: 141
✓
~~~~~~~~~~~~~~~~~~~~~~~~~~~~~~~~~~~~~~~~~~~~~~~~~~~~~~~~~~~~~~~~~~~~~~~~~~~~~~~~~~~~~~~~~~~~~~~~~~~~~~~
Start creating 9 sketches.
✓
~~~~~~~~~~~~~~~~~~~~~~~~~~~~~~~~~~~~~~~~~~~~~~~~~~~~~~~~~~~~~~~~~~~~~~~~~~~~~~~~~~~~~~~~~~~~~~~~~~~~~~~
x Lines where no transformation is found:[]
✓ Number of created sketches:9
Time needed: 0.01 minutes.

+*+*+*+*+*+*+*+*+*+*+*+*+*+*+*+*+*+*+*+*+*+*+*+*+*+*+*+*+*+*+*+*+*+*+*+*+*+*+*+*+*+*+*+*+*+*+*+*+*+*+*+

                                          BUG: 29

+*+*+*+*+*+*+*+*+*+*+*+*+*+*+*+*+*+*+*+*+*+*+*+*+*+*+*+*+*+*+*+*+*+*+*+*+*+*+*+*+*+*+*+*+*+*+*+*+*+*+*+
GIT RESET TO: 07efdd9136966ffe143ea57e15b1a57b5698fd5a
HEAD is now at 07efdd91 Merge pull request #875 from ystopia/foo
bug_file = /Users/daniel/BA_SketchFix_Evaluation/Evaluation/Projects/luigi/luigi/task_register.py
bug_test_file = /Users/daniel/BA_SketchFix_Evaluation/Evaluation/Projects/luigi/test/task_test.py
TEST EXECUTION:
task_test (unittest.loader._FailedTest) ... ERROR

======================================================================
ERROR: task_test (unittest.loader._FailedTest)
----------------------------------------------------------------------
ImportError: Failed to import test module: task_test
Traceback (most recent call last):
  File "/usr/local/Cellar/python/3.7.7/Frameworks/Python.framework/Versions/3.7/lib/python3.7/unittest/loader.py", line 436, in _find_test_path
    module = self._get_module_from_name(name)
  File "/usr/local/Cellar/python/3.7.7/Frameworks/Python.framework/Versions/3.7/lib/python3.7/unittest/loader.py", line 377, in _get_module_from_name
    __import__(name)
  File "/Users/daniel/BA_SketchFix_Evaluation/Evaluation/Projects/luigi/test/task_test.py", line 19, in <module>
    from helpers import unittest
  File "/Users/daniel/BA_SketchFix_Evaluation/Evaluation/Projects/luigi/test/helpers.py", line 21, in <module>
    from luigi import six
ModuleNotFoundError: No module named 'luigi'


----------------------------------------------------------------------
Ran 1 test in 0.000s

FAILED (errors=1)
...........................
x TEST FAILS
✓ PyFix is started...

~~~~~~~~~~~~~~~~~~~~~~~~~~~~~~~~~~~~~~~~~~~~~~~~~~~~~~~~~~~~~~~~~~~~~~~~~~~~~~~~~~~~~~~~~~~~~~~~~~~~~~~

	                              PySketchFix®: Sketches are created.

~~~~~~~~~~~~~~~~~~~~~~~~~~~~~~~~~~~~~~~~~~~~~~~~~~~~~~~~~~~~~~~~~~~~~~~~~~~~~~~~~~~~~~~~~~~~~~~~~~~~~~~
PySketchFix will run with:
bug file: /Users/daniel/BA_SketchFix_Evaluation/Evaluation/Projects/luigi/luigi/task_register.py
~~~~~~~~~~~~~~~~~~~~~~~~~~~~~~~~~~~~~~~~~~~~~~~~~~~~~~~~~~~~~~~~~~~~~~~~~~~~~~~~~~~~~~~~~~~~~~~~~~~~~~~
The suspicious lines which are taken are: [57, 62, 63, 138, 139]
~~~~~~~~~~~~~~~~~~~~~~~~~~~~~~~~~~~~~~~~~~~~~~~~~~~~~~~~~~~~~~~~~~~~~~~~~~~~~~~~~~~~~~~~~~~~~~~~~~~~~~~
Start transforming line: 57
x Fail! Line: 57 could not be transformed: ''
Start transforming line: 62
✓
Start transforming line: 63
✓
Start transforming line: 138
✓
Start transforming line: 139
x Fail! Line: 139 could not be transformed: 'continue'
~~~~~~~~~~~~~~~~~~~~~~~~~~~~~~~~~~~~~~~~~~~~~~~~~~~~~~~~~~~~~~~~~~~~~~~~~~~~~~~~~~~~~~~~~~~~~~~~~~~~~~~
Start creating 503 sketches.
✓
~~~~~~~~~~~~~~~~~~~~~~~~~~~~~~~~~~~~~~~~~~~~~~~~~~~~~~~~~~~~~~~~~~~~~~~~~~~~~~~~~~~~~~~~~~~~~~~~~~~~~~~
x Lines where no transformation is found:[57, 139]
✓ Number of created sketches:503
Time needed: 0.03 minutes.

+*+*+*+*+*+*+*+*+*+*+*+*+*+*+*+*+*+*+*+*+*+*+*+*+*+*+*+*+*+*+*+*+*+*+*+*+*+*+*+*+*+*+*+*+*+*+*+*+*+*+*+

                                          BUG: 30

+*+*+*+*+*+*+*+*+*+*+*+*+*+*+*+*+*+*+*+*+*+*+*+*+*+*+*+*+*+*+*+*+*+*+*+*+*+*+*+*+*+*+*+*+*+*+*+*+*+*+*+
GIT RESET TO: 97fa4afea3748f0d714482d2c97990bb467bc9d1
HEAD is now at 97fa4afe Merge pull request #867 from spotify/erikbern/worker-cleanup
bug_file = /Users/daniel/BA_SketchFix_Evaluation/Evaluation/Projects/luigi/luigi/worker.py
bug_test_file = /Users/daniel/BA_SketchFix_Evaluation/Evaluation/Projects/luigi/test/test_event_callbacks.py
TEST EXECUTION:
...........................
x TEST FAILS
✓ PyFix is started...

~~~~~~~~~~~~~~~~~~~~~~~~~~~~~~~~~~~~~~~~~~~~~~~~~~~~~~~~~~~~~~~~~~~~~~~~~~~~~~~~~~~~~~~~~~~~~~~~~~~~~~~

	                              PySketchFix®: Sketches are created.

~~~~~~~~~~~~~~~~~~~~~~~~~~~~~~~~~~~~~~~~~~~~~~~~~~~~~~~~~~~~~~~~~~~~~~~~~~~~~~~~~~~~~~~~~~~~~~~~~~~~~~~
PySketchFix will run with:
bug file: /Users/daniel/BA_SketchFix_Evaluation/Evaluation/Projects/luigi/luigi/worker.py
~~~~~~~~~~~~~~~~~~~~~~~~~~~~~~~~~~~~~~~~~~~~~~~~~~~~~~~~~~~~~~~~~~~~~~~~~~~~~~~~~~~~~~~~~~~~~~~~~~~~~~~
test_event_callbacks (unittest.loader._FailedTest) ... ERROR

======================================================================
ERROR: test_event_callbacks (unittest.loader._FailedTest)
----------------------------------------------------------------------
ImportError: Failed to import test module: test_event_callbacks
Traceback (most recent call last):
  File "/usr/local/Cellar/python/3.7.7/Frameworks/Python.framework/Versions/3.7/lib/python3.7/unittest/loader.py", line 436, in _find_test_path
    module = self._get_module_from_name(name)
  File "/usr/local/Cellar/python/3.7.7/Frameworks/Python.framework/Versions/3.7/lib/python3.7/unittest/loader.py", line 377, in _get_module_from_name
    __import__(name)
  File "/Users/daniel/BA_SketchFix_Evaluation/Evaluation/Projects/luigi/test/test_event_callbacks.py", line 19, in <module>
    from helpers import unittest
  File "/Users/daniel/BA_SketchFix_Evaluation/Evaluation/Projects/luigi/test/helpers.py", line 21, in <module>
    from luigi import six
ModuleNotFoundError: No module named 'luigi'


----------------------------------------------------------------------
Ran 1 test in 0.000s

FAILED (errors=1)
The suspicious lines which are taken are: [188, 189, 190, 191, 192]
~~~~~~~~~~~~~~~~~~~~~~~~~~~~~~~~~~~~~~~~~~~~~~~~~~~~~~~~~~~~~~~~~~~~~~~~~~~~~~~~~~~~~~~~~~~~~~~~~~~~~~~
Start transforming line: 188
x Fail! Line: 188 could not be transformed: 'try'
Start transforming line: 189
x Fail! Line: 189 could not be transformed: 'new_deps = self._run_get_new_deps()'
Start transforming line: 190
✓
Start transforming line: 191
✓
Start transforming line: 192
x Fail! Line: 192 could not be transformed: ''
~~~~~~~~~~~~~~~~~~~~~~~~~~~~~~~~~~~~~~~~~~~~~~~~~~~~~~~~~~~~~~~~~~~~~~~~~~~~~~~~~~~~~~~~~~~~~~~~~~~~~~~
Start creating 43 sketches.
✓
~~~~~~~~~~~~~~~~~~~~~~~~~~~~~~~~~~~~~~~~~~~~~~~~~~~~~~~~~~~~~~~~~~~~~~~~~~~~~~~~~~~~~~~~~~~~~~~~~~~~~~~
x Lines where no transformation is found:[188, 189, 192]
✓ Number of created sketches:43
Time needed: 0.02 minutes.

+*+*+*+*+*+*+*+*+*+*+*+*+*+*+*+*+*+*+*+*+*+*+*+*+*+*+*+*+*+*+*+*+*+*+*+*+*+*+*+*+*+*+*+*+*+*+*+*+*+*+*+

                                          BUG: 31

+*+*+*+*+*+*+*+*+*+*+*+*+*+*+*+*+*+*+*+*+*+*+*+*+*+*+*+*+*+*+*+*+*+*+*+*+*+*+*+*+*+*+*+*+*+*+*+*+*+*+*+
GIT RESET TO: 554850f32784537796383db5ee188d0455863ca9
HEAD is now at 554850f3 bumped version to 1.1.3 for next release
bug_file = /Users/daniel/BA_SketchFix_Evaluation/Evaluation/Projects/luigi/luigi/scheduler.py
bug_test_file = /Users/daniel/BA_SketchFix_Evaluation/Evaluation/Projects/luigi/test/central_planner_test.py
TEST EXECUTION:
central_planner_test (unittest.loader._FailedTest) ... ERROR

======================================================================
ERROR: central_planner_test (unittest.loader._FailedTest)
----------------------------------------------------------------------
ImportError: Failed to import test module: central_planner_test
Traceback (most recent call last):
  File "/usr/local/Cellar/python/3.7.7/Frameworks/Python.framework/Versions/3.7/lib/python3.7/unittest/loader.py", line 436, in _find_test_path
    module = self._get_module_from_name(name)
  File "/usr/local/Cellar/python/3.7.7/Frameworks/Python.framework/Versions/3.7/lib/python3.7/unittest/loader.py", line 377, in _get_module_from_name
    __import__(name)
  File "/Users/daniel/BA_SketchFix_Evaluation/Evaluation/Projects/luigi/test/central_planner_test.py", line 19, in <module>
    from helpers import unittest
  File "/Users/daniel/BA_SketchFix_Evaluation/Evaluation/Projects/luigi/test/helpers.py", line 21, in <module>
    from luigi import six
ModuleNotFoundError: No module named 'luigi'


----------------------------------------------------------------------
Ran 1 test in 0.000s

FAILED (errors=1)
...........................
x TEST FAILS
✓ PyFix is started...

~~~~~~~~~~~~~~~~~~~~~~~~~~~~~~~~~~~~~~~~~~~~~~~~~~~~~~~~~~~~~~~~~~~~~~~~~~~~~~~~~~~~~~~~~~~~~~~~~~~~~~~

	                              PySketchFix®: Sketches are created.

~~~~~~~~~~~~~~~~~~~~~~~~~~~~~~~~~~~~~~~~~~~~~~~~~~~~~~~~~~~~~~~~~~~~~~~~~~~~~~~~~~~~~~~~~~~~~~~~~~~~~~~
PySketchFix will run with:
bug file: /Users/daniel/BA_SketchFix_Evaluation/Evaluation/Projects/luigi/luigi/scheduler.py
~~~~~~~~~~~~~~~~~~~~~~~~~~~~~~~~~~~~~~~~~~~~~~~~~~~~~~~~~~~~~~~~~~~~~~~~~~~~~~~~~~~~~~~~~~~~~~~~~~~~~~~
The suspicious lines which are taken are: [656]
~~~~~~~~~~~~~~~~~~~~~~~~~~~~~~~~~~~~~~~~~~~~~~~~~~~~~~~~~~~~~~~~~~~~~~~~~~~~~~~~~~~~~~~~~~~~~~~~~~~~~~~
Start transforming line: 656
✓
~~~~~~~~~~~~~~~~~~~~~~~~~~~~~~~~~~~~~~~~~~~~~~~~~~~~~~~~~~~~~~~~~~~~~~~~~~~~~~~~~~~~~~~~~~~~~~~~~~~~~~~
Start creating 13 sketches.
✓
~~~~~~~~~~~~~~~~~~~~~~~~~~~~~~~~~~~~~~~~~~~~~~~~~~~~~~~~~~~~~~~~~~~~~~~~~~~~~~~~~~~~~~~~~~~~~~~~~~~~~~~
x Lines where no transformation is found:[]
✓ Number of created sketches:13
Time needed: 0.01 minutes.

+*+*+*+*+*+*+*+*+*+*+*+*+*+*+*+*+*+*+*+*+*+*+*+*+*+*+*+*+*+*+*+*+*+*+*+*+*+*+*+*+*+*+*+*+*+*+*+*+*+*+*+

                                          BUG: 32

+*+*+*+*+*+*+*+*+*+*+*+*+*+*+*+*+*+*+*+*+*+*+*+*+*+*+*+*+*+*+*+*+*+*+*+*+*+*+*+*+*+*+*+*+*+*+*+*+*+*+*+
GIT RESET TO: 7233a0cc3e34c7c14259b1fa046f66332914f410
HEAD is now at 7233a0cc 1.1.2 in master from now on
bug_file = /Users/daniel/BA_SketchFix_Evaluation/Evaluation/Projects/luigi/luigi/task_register.py
bug_test_file = /Users/daniel/BA_SketchFix_Evaluation/Evaluation/Projects/luigi/test/instance_test.py
TEST EXECUTION:
...........................
x TEST FAILS
x FAIL! Suspicious lines are empty!

+*+*+*+*+*+*+*+*+*+*+*+*+*+*+*+*+*+*+*+*+*+*+*+*+*+*+*+*+*+*+*+*+*+*+*+*+*+*+*+*+*+*+*+*+*+*+*+*+*+*+*+

                                          BUG: 33

+*+*+*+*+*+*+*+*+*+*+*+*+*+*+*+*+*+*+*+*+*+*+*+*+*+*+*+*+*+*+*+*+*+*+*+*+*+*+*+*+*+*+*+*+*+*+*+*+*+*+*+
GIT RESET TO: a7c0662eab78fd226fd7ef6b4461d7199336cbb1
instance_test (unittest.loader._FailedTest) ... ERROR

======================================================================
ERROR: instance_test (unittest.loader._FailedTest)
----------------------------------------------------------------------
ImportError: Failed to import test module: instance_test
Traceback (most recent call last):
  File "/usr/local/Cellar/python/3.7.7/Frameworks/Python.framework/Versions/3.7/lib/python3.7/unittest/loader.py", line 436, in _find_test_path
    module = self._get_module_from_name(name)
  File "/usr/local/Cellar/python/3.7.7/Frameworks/Python.framework/Versions/3.7/lib/python3.7/unittest/loader.py", line 377, in _get_module_from_name
    __import__(name)
  File "/Users/daniel/BA_SketchFix_Evaluation/Evaluation/Projects/luigi/test/instance_test.py", line 18, in <module>
    from helpers import unittest
  File "/Users/daniel/BA_SketchFix_Evaluation/Evaluation/Projects/luigi/test/helpers.py", line 21, in <module>
    from luigi import six
ModuleNotFoundError: No module named 'luigi'


----------------------------------------------------------------------
Ran 1 test in 0.000s

FAILED (errors=1)
HEAD is now at a7c0662e TestRemoveGlobalParameters: Check exit code
bug_file = /Users/daniel/BA_SketchFix_Evaluation/Evaluation/Projects/luigi/luigi/task.py
bug_test_file = /Users/daniel/BA_SketchFix_Evaluation/Evaluation/Projects/luigi/test/parameter_test.py
TEST EXECUTION:
parameter_test (unittest.loader._FailedTest) ... ERROR

======================================================================
ERROR: parameter_test (unittest.loader._FailedTest)
----------------------------------------------------------------------
ImportError: Failed to import test module: parameter_test
Traceback (most recent call last):
  File "/usr/local/Cellar/python/3.7.7/Frameworks/Python.framework/Versions/3.7/lib/python3.7/unittest/loader.py", line 436, in _find_test_path
    module = self._get_module_from_name(name)
  File "/usr/local/Cellar/python/3.7.7/Frameworks/Python.framework/Versions/3.7/lib/python3.7/unittest/loader.py", line 377, in _get_module_from_name
    __import__(name)
  File "/Users/daniel/BA_SketchFix_Evaluation/Evaluation/Projects/luigi/test/parameter_test.py", line 22, in <module>
    import luigi
ModuleNotFoundError: No module named 'luigi'


----------------------------------------------------------------------
Ran 1 test in 0.000s

FAILED (errors=1)
...........................
x TEST FAILS
✓ PyFix is started...

~~~~~~~~~~~~~~~~~~~~~~~~~~~~~~~~~~~~~~~~~~~~~~~~~~~~~~~~~~~~~~~~~~~~~~~~~~~~~~~~~~~~~~~~~~~~~~~~~~~~~~~

	                              PySketchFix®: Sketches are created.

~~~~~~~~~~~~~~~~~~~~~~~~~~~~~~~~~~~~~~~~~~~~~~~~~~~~~~~~~~~~~~~~~~~~~~~~~~~~~~~~~~~~~~~~~~~~~~~~~~~~~~~
PySketchFix will run with:
bug file: /Users/daniel/BA_SketchFix_Evaluation/Evaluation/Projects/luigi/luigi/task.py
~~~~~~~~~~~~~~~~~~~~~~~~~~~~~~~~~~~~~~~~~~~~~~~~~~~~~~~~~~~~~~~~~~~~~~~~~~~~~~~~~~~~~~~~~~~~~~~~~~~~~~~
The suspicious lines which are taken are: [334]
~~~~~~~~~~~~~~~~~~~~~~~~~~~~~~~~~~~~~~~~~~~~~~~~~~~~~~~~~~~~~~~~~~~~~~~~~~~~~~~~~~~~~~~~~~~~~~~~~~~~~~~
Start transforming line: 334
x Fail! Line: 334 could not be transformed: 'positional_params = [(n, p) n, p in params p.significant]'
~~~~~~~~~~~~~~~~~~~~~~~~~~~~~~~~~~~~~~~~~~~~~~~~~~~~~~~~~~~~~~~~~~~~~~~~~~~~~~~~~~~~~~~~~~~~~~~~~~~~~~~
Start creating 0 sketches.
✓
~~~~~~~~~~~~~~~~~~~~~~~~~~~~~~~~~~~~~~~~~~~~~~~~~~~~~~~~~~~~~~~~~~~~~~~~~~~~~~~~~~~~~~~~~~~~~~~~~~~~~~~
x Lines where no transformation is found:[334]
✓ Number of created sketches:0
Time needed: 0.0 minutes.
#######################################################################################################
Results with bug numbers:
Project:luigi
Failing:[1, 3, 4, 5, 6, 7, 8, 9, 10, 11, 13, 14, 15, 16, 18, 19, 22, 23, 27, 28, 29, 30, 31, 33]
Empty Sus Lines: [32]
Passing[]
Not Found[12, 26]

Process finished with exit code 0
