
#######################################################################################################
                             PROJECT: Pysnooper
#######################################################################################################
CLONING PROJECT:
✓ SUCCESSFUL! This project is already cloned: https://github.com/cool-RR/PySnooper
.......................................................................................................
BUGGY LINES:
Suspicious lines to bug1:
87,133,257,276
Suspicious lines to bug2:
28,87,133,250,310
Suspicious lines to bug3:
26
.......................................................................................................

+*+*+*+*+*+*+*+*+*+*+*+*+*+*+*+*+*+*+*+*+*+*+*+*+*+*+*+*+*+*+*+*+*+*+*+*+*+*+*+*+*+*+*+*+*+*+*+*+*+

                                          BUG: 1

+*+*+*+*+*+*+*+*+*+*+*+*+*+*+*+*+*+*+*+*+*+*+*+*+*+*+*+*+*+*+*+*+*+*+*+*+*+*+*+*+*+*+*+*+*+*+*+*+*+
GIT RESET TO: e21a31162f4c54be693d8ca8260e42393b39abd3
x FAIL! The TEST file: /Users/daniel/Bachelorarbeit/Projects/Pysnooper/tests/test_chinese.py to the project Pysnooper with bug: 1does not exists. Next bug is taken

+*+*+*+*+*+*+*+*+*+*+*+*+*+*+*+*+*+*+*+*+*+*+*+*+*+*+*+*+*+*+*+*+*+*+*+*+*+*+*+*+*+*+*+*+*+*+*+*+*+

                                          BUG: 2

+*+*+*+*+*+*+*+*+*+*+*+*+*+*+*+*+*+*+*+*+*+*+*+*+*+*+*+*+*+*+*+*+*+*+*+*+*+*+*+*+*+*+*+*+*+*+*+*+*+
GIT RESET TO: e21a31162f4c54be693d8ca8260e42393b39abd3
bug_file = /Users/daniel/Bachelorarbeit/Projects/Pysnooper/pysnooper/tracer.py
bug_test_file = /Users/daniel/Bachelorarbeit/Projects/Pysnooper/tests/test_pysnooper.py
TEST EXECUTION:
x FAIL! Test fails or has errors.
✓ PySketchFix is started...
~~~~~~~~~~~~~~~~~~~~~~~~~~~~~~~~~~~~~~~~~~~~~~~~~~~~~~~~~~~~~~~~~~~~~~~~~~~~~~~~~~~~~~~~~~~~~~~~~~~~~~~

	                              PySketchFix®: Sketches are created.

~~~~~~~~~~~~~~~~~~~~~~~~~~~~~~~~~~~~~~~~~~~~~~~~~~~~~~~~~~~~~~~~~~~~~~~~~~~~~~~~~~~~~~~~~~~~~~~~~~~~~~~
PySketchFix will run with:
bug file: /Users/daniel/Bachelorarbeit/Projects/Pysnooper/pysnooper/tracer.py
~~~~~~~~~~~~~~~~~~~~~~~~~~~~~~~~~~~~~~~~~~~~~~~~~~~~~~~~~~~~~~~~~~~~~~~~~~~~~~~~~~~~~~~~~~~~~~~~~~~~~~~
The suspicious lines which are taken are: [28, 87, 133, 250, 310]
~~~~~~~~~~~~~~~~~~~~~~~~~~~~~~~~~~~~~~~~~~~~~~~~~~~~~~~~~~~~~~~~~~~~~~~~~~~~~~~~~~~~~~~~~~~~~~~~~~~~~~~
Start transforming line: 28
✓
Start transforming line: 87
x Fail! Line: 87 could not be transformed: 'encoding = 'ascii''
Start transforming line: 133
x Fail! Line: 133 could not be transformed: 'with open(self.path, 'w' self.overwrite 'a') as output_file'
Start transforming line: 250
✓
Start transforming line: 310
x Fail! Line: 310 could not be transformed: '   get_local_reprs(frame, watch=self.watch)'
~~~~~~~~~~~~~~~~~~~~~~~~~~~~~~~~~~~~~~~~~~~~~~~~~~~~~~~~~~~~~~~~~~~~~~~~~~~~~~~~~~~~~~~~~~~~~~~~~~~~~~~
Start creating 24 sketches.
✓
~~~~~~~~~~~~~~~~~~~~~~~~~~~~~~~~~~~~~~~~~~~~~~~~~~~~~~~~~~~~~~~~~~~~~~~~~~~~~~~~~~~~~~~~~~~~~~~~~~~~~~~
x Lines where no transformation is found:[87, 133, 310]
✓ Number of created sketches:24
Time needed: 0.06 minutes.

+*+*+*+*+*+*+*+*+*+*+*+*+*+*+*+*+*+*+*+*+*+*+*+*+*+*+*+*+*+*+*+*+*+*+*+*+*+*+*+*+*+*+*+*+*+*+*+*+*+

                                          BUG: 3

+*+*+*+*+*+*+*+*+*+*+*+*+*+*+*+*+*+*+*+*+*+*+*+*+*+*+*+*+*+*+*+*+*+*+*+*+*+*+*+*+*+*+*+*+*+*+*+*+*+
GIT RESET TO: 6e3d797be3fa0a746fb5b1b7c7fea78eb926c208
bug_file = /Users/daniel/Bachelorarbeit/Projects/Pysnooper/pysnooper/pysnooper.py
bug_test_file = /Users/daniel/Bachelorarbeit/Projects/Pysnooper/tests/test_pysnooper.py
TEST EXECUTION:
x FAIL! Test fails or has errors.
✓ PySketchFix is started...
~~~~~~~~~~~~~~~~~~~~~~~~~~~~~~~~~~~~~~~~~~~~~~~~~~~~~~~~~~~~~~~~~~~~~~~~~~~~~~~~~~~~~~~~~~~~~~~~~~~~~~~

	                              PySketchFix®: Sketches are created.

~~~~~~~~~~~~~~~~~~~~~~~~~~~~~~~~~~~~~~~~~~~~~~~~~~~~~~~~~~~~~~~~~~~~~~~~~~~~~~~~~~~~~~~~~~~~~~~~~~~~~~~
PySketchFix will run with:
bug file: /Users/daniel/Bachelorarbeit/Projects/Pysnooper/pysnooper/pysnooper.py
~~~~~~~~~~~~~~~~~~~~~~~~~~~~~~~~~~~~~~~~~~~~~~~~~~~~~~~~~~~~~~~~~~~~~~~~~~~~~~~~~~~~~~~~~~~~~~~~~~~~~~~
The suspicious lines which are taken are: [26]
~~~~~~~~~~~~~~~~~~~~~~~~~~~~~~~~~~~~~~~~~~~~~~~~~~~~~~~~~~~~~~~~~~~~~~~~~~~~~~~~~~~~~~~~~~~~~~~~~~~~~~~
Start transforming line: 26
x Fail! Line: 26 could not be transformed: 'with open(output_path, 'a') as output_file'
~~~~~~~~~~~~~~~~~~~~~~~~~~~~~~~~~~~~~~~~~~~~~~~~~~~~~~~~~~~~~~~~~~~~~~~~~~~~~~~~~~~~~~~~~~~~~~~~~~~~~~~
Start creating 0 sketches.
✓
~~~~~~~~~~~~~~~~~~~~~~~~~~~~~~~~~~~~~~~~~~~~~~~~~~~~~~~~~~~~~~~~~~~~~~~~~~~~~~~~~~~~~~~~~~~~~~~~~~~~~~~
x Lines where no transformation is found:[26]
✓ Number of created sketches:0
Time needed: 0.01 minutes.
#######################################################################################################
Results with bug numbers:
Project:Pysnooper
Failing:[2, 3]
Passing:[]
Empty Suspicious Lines:[]
No bug information is found:[1]
